<sdf version='1.6'>
  <world name='default'>
    <gui fullscreen='0'>
      <camera name='user_camera'>
        <pose frame=''>0.216264 3.38336 2.3557 0 0.471999 -0.900014</pose>
        <view_controller>orbit</view_controller>
        <projection_type>perspective</projection_type>
      </camera>
    </gui>
    <light name='sun' type='directional'>
      <cast_shadows>1</cast_shadows>
      <pose frame=''>0 0 10 0 -0 0</pose>
      <diffuse>0.8 0.8 0.8 1</diffuse>
      <specular>0.2 0.2 0.2 1</specular>
      <attenuation>
        <range>1000</range>
        <constant>0.9</constant>
        <linear>0.01</linear>
        <quadratic>0.001</quadratic>
      </attenuation>
      <direction>-0.5 0.1 -0.9</direction>
    </light>
    <gravity>0 0 -9.81</gravity>
    <magnetic_field>6e-06 2.3e-05 -4.2e-05</magnetic_field>
    <atmosphere type='adiabatic'/>
    <physics name='default_physics' default='0' type='ode'>
      <max_step_size>0.001</max_step_size>
      <real_time_factor>1</real_time_factor>
      <real_time_update_rate>1000</real_time_update_rate>
    </physics>
    <scene>
      <ambient>1 1 1 1</ambient>
      <background>1 1 1 1</background>
      <shadows>1</shadows>
      <grid>0</grid>
    </scene>
    <wind/>
    <spherical_coordinates>
      <surface_model>EARTH_WGS84</surface_model>
      <latitude_deg>0</latitude_deg>
      <longitude_deg>0</longitude_deg>
      <elevation>0</elevation>
      <heading_deg>0</heading_deg>
    </spherical_coordinates>
    <model name='ground_plane'>
      <static>1</static>
      <link name='link'>
        <collision name='collision'>
          <geometry>
            <plane>
              <normal>0 0 1</normal>
              <size>100 100</size>
            </plane>
          </geometry>
          <surface>
            <friction>
              <ode>
                <mu>100</mu>
                <mu2>50</mu2>
              </ode>
              <torsional>
                <ode/>
              </torsional>
            </friction>
            <contact>
              <ode/>
            </contact>
            <bounce/>
          </surface>
          <max_contacts>10</max_contacts>
        </collision>
        <visual name='visual'>
          <cast_shadows>0</cast_shadows>
          <geometry>
            <plane>
              <normal>0 0 1</normal>
              <size>100 100</size>
            </plane>
          </geometry>
          <material>
            <script>
              <uri>file://media/materials/scripts/gazebo.material</uri>
              <name>Gazebo/Grey</name>
            </script>
          </material>
        </visual>
        <self_collide>0</self_collide>
        <enable_wind>0</enable_wind>
        <kinematic>0</kinematic>
      </link>
      <pose frame=''>0 0 0 0 -0 0</pose>
    </model>
    <model name='visual_pattern'>
      <static>1</static>
      <link name='link'>
        <visual name='visual'>
          <geometry>
            <mesh>
              <uri>model://visual_pattern/meshes/visual_pattern.dae</uri>
              <scale>0.25 0.25 0.25</scale>
            </mesh>
          </geometry>
        </visual>
        <self_collide>0</self_collide>
        <enable_wind>0</enable_wind>
        <kinematic>0</kinematic>
      </link>
      <pose frame=''>4.5 1 1 3.14159 -9.3e-05 3.14159</pose>
    </model>
    <model name='coman'>
      <link name='base_link'>
        <pose frame=''>0 0 0 0 -0 0</pose>
        <inertial>
          <pose frame=''>-0.026643 -0.000617 0.052585 0 -0 0</pose>
          <mass>1.81087</mass>
          <inertia>
            <ixx>0.00510542</ixx>
            <ixy>-5.99912e-05</ixy>
            <ixz>0.00168814</ixz>
            <iyy>0.00626406</iyy>
            <iyz>1.66922e-05</iyz>
            <izz>0.00247385</izz>
          </inertia>
        </inertial>
        <collision name='base_link_fixed_joint_lump__Waist_collision'>
          <pose frame=''>0 0 -0.52 0 -0 -3.14159</pose>
          <geometry>
            <mesh>
              <scale>0.03937 0.03937 0.03937</scale>
              <uri>model://coman_urdf/meshes/simple/Waist.STL</uri>
            </mesh>
          </geometry>
          <surface>
            <contact>
              <ode/>
            </contact>
            <friction>
              <ode/>
              <torsional>
                <ode/>
              </torsional>
            </friction>
            <bounce/>
          </surface>
          <max_contacts>10</max_contacts>
        </collision>
        <visual name='base_link_fixed_joint_lump__Waist_visual'>
          <pose frame=''>0 0 -0.52 0 -0 -3.14159</pose>
          <geometry>
            <mesh>
              <scale>0.03937 0.03937 0.03937</scale>
              <uri>model://coman_urdf/meshes/Waist.STL</uri>
            </mesh>
          </geometry>
          <material>
            <script>
              <name>Gazebo/DarkGrey</name>
              <uri>file://media/materials/scripts/gazebo.material</uri>
            </script>
          </material>
        </visual>
        <visual name='base_link_fixed_joint_lump__imu_link_visual_1'>
          <pose frame=''>-0.072 -0.0068 0.044 1.5708 -0 1.5708</pose>
          <geometry>
            <box>
              <size>0.01 0.01 0.01</size>
            </box>
          </geometry>
          <material>
            <script>
              <uri>__default__</uri>
              <name>__default__</name>
            </script>
          </material>
        </visual>
        <velocity_decay/>
        <gravity>1</gravity>
        <velocity_decay/>
        <sensor name='imu_sensor' type='imu'>
          <always_on>1</always_on>
          <update_rate>1000</update_rate>
          <visualize>1</visualize>
          <topic>__default_topic__</topic>
          <imu>
            <angular_velocity/>
            <linear_acceleration/>
          </imu>
          <pose frame=''>-0.072 -0.0068 0.044 1.5708 -0 1.5708</pose>
        </sensor>
        <self_collide>0</self_collide>
        <enable_wind>0</enable_wind>
        <kinematic>0</kinematic>
      </link>
      <link name='LHipMot'>
        <pose frame=''>0 0.023 0 0 -0 0</pose>
        <inertial>
          <pose frame=''>-0.000327 0.023587 -0.000265 0 -0 0</pose>
          <mass>0.892582</mass>
          <inertia>
            <ixx>0.000476723</ixx>
            <ixy>3.99366e-06</ixy>
            <ixz>-2.48026e-06</ixz>
            <iyy>0.000545804</iyy>
            <iyz>3.33896e-06</iyz>
            <izz>0.000512686</izz>
          </inertia>
        </inertial>
        <collision name='LHipMot_collision'>
          <pose frame=''>0 -0.023 -0.52 0 -0 -3.14159</pose>
          <geometry>
            <mesh>
              <scale>0.03937 -0.03937 0.03937</scale>
              <uri>model://coman_urdf/meshes/simple/Leg0.STL</uri>
            </mesh>
          </geometry>
          <surface>
            <contact>
              <ode/>
            </contact>
            <friction>
              <ode/>
              <torsional>
                <ode/>
              </torsional>
            </friction>
            <bounce/>
          </surface>
          <max_contacts>10</max_contacts>
        </collision>
        <visual name='LHipMot_visual'>
          <pose frame=''>0 -0.023 -0.52 0 -0 -3.14159</pose>
          <geometry>
            <mesh>
              <scale>0.03937 -0.03937 0.03937</scale>
              <uri>model://coman_urdf/meshes/Leg0.STL</uri>
            </mesh>
          </geometry>
          <material>
            <script>
              <name>Gazebo/DarkGrey</name>
              <uri>file://media/materials/scripts/gazebo.material</uri>
            </script>
          </material>
        </visual>
        <gravity>1</gravity>
        <velocity_decay/>
        <self_collide>0</self_collide>
        <enable_wind>0</enable_wind>
        <kinematic>0</kinematic>
      </link>
      <joint name='LHipSag' type='revolute'>
        <child>LHipMot</child>
        <parent>base_link</parent>
        <axis>
          <xyz>0 1 0</xyz>
          <limit>
            <lower>-1.9199</lower>
            <upper>0.7854</upper>
            <effort>50</effort>
            <velocity>4</velocity>
          </limit>
          <dynamics>
            <damping>3</damping>
            <friction>0</friction>
            <spring_reference>0</spring_reference>
            <spring_stiffness>0</spring_stiffness>
          </dynamics>
          <use_parent_model_frame>1</use_parent_model_frame>
        </axis>
        <physics>
          <provide_feedback>1</provide_feedback>
          <ode>
            <provide_feedback>1</provide_feedback>
            <implicit_spring_damper>1</implicit_spring_damper>
            <cfm_damping>1</cfm_damping>
            <limit>
              <cfm>0</cfm>
              <erp>0.2</erp>
            </limit>
          </ode>
        </physics>
      </joint>
      <link name='LThighUpLeg'>
        <pose frame=''>0 0.0726 0 0 -0 0</pose>
        <inertial>
          <pose frame=''>0.001259 0.016896 -0.058903 0 -0 0</pose>
          <mass>1.02461</mass>
          <inertia>
            <ixx>0.000916572</ixx>
            <ixy>1.44499e-06</ixy>
            <ixz>-1.6685e-05</ixz>
            <iyy>0.0010485</iyy>
            <iyz>-2.54929e-05</iyz>
            <izz>0.000686372</izz>
          </inertia>
        </inertial>
        <collision name='LThighUpLeg_collision'>
          <pose frame=''>0 -0.0726 -0.52 0 -0 -3.14159</pose>
          <geometry>
            <mesh>
              <scale>0.03937 -0.03937 0.03937</scale>
              <uri>model://coman_urdf/meshes/simple/Leg1.STL</uri>
            </mesh>
          </geometry>
          <surface>
            <contact>
              <ode/>
            </contact>
            <friction>
              <ode/>
              <torsional>
                <ode/>
              </torsional>
            </friction>
            <bounce/>
          </surface>
          <max_contacts>10</max_contacts>
        </collision>
        <visual name='LThighUpLeg_visual'>
          <pose frame=''>0 -0.0726 -0.52 0 -0 -3.14159</pose>
          <geometry>
            <mesh>
              <scale>0.03937 -0.03937 0.03937</scale>
              <uri>model://coman_urdf/meshes/Leg1.STL</uri>
            </mesh>
          </geometry>
          <material>
            <script>
              <name>Gazebo/DarkGrey</name>
              <uri>file://media/materials/scripts/gazebo.material</uri>
            </script>
          </material>
        </visual>
        <gravity>1</gravity>
        <velocity_decay/>
        <self_collide>0</self_collide>
        <enable_wind>0</enable_wind>
        <kinematic>0</kinematic>
      </link>
      <joint name='LHipLat' type='revolute'>
        <child>LThighUpLeg</child>
        <parent>LHipMot</parent>
        <axis>
          <xyz>1 0 0</xyz>
          <limit>
            <lower>-0.4363</lower>
            <upper>1.0472</upper>
            <effort>50</effort>
            <velocity>4</velocity>
          </limit>
          <dynamics>
            <damping>3</damping>
            <friction>0</friction>
            <spring_reference>0</spring_reference>
            <spring_stiffness>0</spring_stiffness>
          </dynamics>
          <use_parent_model_frame>1</use_parent_model_frame>
        </axis>
        <physics>
          <provide_feedback>1</provide_feedback>
          <ode>
            <provide_feedback>1</provide_feedback>
            <implicit_spring_damper>1</implicit_spring_damper>
            <cfm_damping>1</cfm_damping>
            <limit>
              <cfm>0</cfm>
              <erp>0.2</erp>
            </limit>
          </ode>
        </physics>
      </joint>
      <link name='LThighLowLeg'>
        <pose frame=''>0 0.0726 -0.1024 0 -0 0</pose>
        <inertial>
          <pose frame=''>0.000987 -0.00067 -0.075717 0 -0 0</pose>
          <mass>1.70011</mass>
          <inertia>
            <ixx>0.00389795</ixx>
            <ixy>-1.78024e-06</ixy>
            <ixz>2.64033e-05</ixz>
            <iyy>0.00393608</iyy>
            <iyz>-4.52271e-05</iyz>
            <izz>0.000902187</izz>
          </inertia>
        </inertial>
        <collision name='LThighLowLeg_collision'>
          <pose frame=''>0 -0.0726 -0.4176 0 -0 -3.14159</pose>
          <geometry>
            <mesh>
              <scale>0.03937 -0.03937 0.03937</scale>
              <uri>model://coman_urdf/meshes/simple/Leg2.STL</uri>
            </mesh>
          </geometry>
          <surface>
            <contact>
              <ode/>
            </contact>
            <friction>
              <ode/>
              <torsional>
                <ode/>
              </torsional>
            </friction>
            <bounce/>
          </surface>
          <max_contacts>10</max_contacts>
        </collision>
        <visual name='LThighLowLeg_visual'>
          <pose frame=''>0 -0.0726 -0.4176 0 -0 -3.14159</pose>
          <geometry>
            <mesh>
              <scale>0.03937 -0.03937 0.03937</scale>
              <uri>model://coman_urdf/meshes/Leg2.STL</uri>
            </mesh>
          </geometry>
          <material>
            <script>
              <name>Gazebo/DarkGrey</name>
              <uri>file://media/materials/scripts/gazebo.material</uri>
            </script>
          </material>
        </visual>
        <gravity>1</gravity>
        <velocity_decay/>
        <self_collide>0</self_collide>
        <enable_wind>0</enable_wind>
        <kinematic>0</kinematic>
      </link>
      <joint name='LHipYaw' type='revolute'>
        <child>LThighLowLeg</child>
        <parent>LThighUpLeg</parent>
        <axis>
          <xyz>0 0 1</xyz>
          <limit>
            <lower>-0.8727</lower>
            <upper>0.8727</upper>
            <effort>50</effort>
            <velocity>4</velocity>
          </limit>
          <dynamics>
            <damping>3</damping>
            <friction>0</friction>
            <spring_reference>0</spring_reference>
            <spring_stiffness>0</spring_stiffness>
          </dynamics>
          <use_parent_model_frame>1</use_parent_model_frame>
        </axis>
        <physics>
          <provide_feedback>1</provide_feedback>
          <ode>
            <provide_feedback>1</provide_feedback>
            <implicit_spring_damper>1</implicit_spring_damper>
            <cfm_damping>1</cfm_damping>
            <limit>
              <cfm>0</cfm>
              <erp>0.2</erp>
            </limit>
          </ode>
        </physics>
      </joint>
      <link name='LLowLeg'>
        <pose frame=''>0 0.0726 -0.2258 0 -0 0</pose>
        <inertial>
          <pose frame=''>0.002461 0.00531 -0.08599 0 -0 0</pose>
          <mass>1.40982</mass>
          <inertia>
            <ixx>0.0040604</ixx>
            <ixy>-1.12272e-05</ixy>
            <ixz>1.2261e-05</ixz>
            <iyy>0.00400565</iyy>
            <iyz>-0.000518992</iyz>
            <izz>0.00124141</izz>
          </inertia>
        </inertial>
        <collision name='LLowLeg_collision'>
          <pose frame=''>0 -0.0726 -0.2942 0 -0 -3.14159</pose>
          <geometry>
            <mesh>
              <scale>0.03937 -0.03937 0.03937</scale>
              <uri>model://coman_urdf/meshes/simple/Leg3.STL</uri>
            </mesh>
          </geometry>
          <surface>
            <contact>
              <ode/>
            </contact>
            <friction>
              <ode/>
              <torsional>
                <ode/>
              </torsional>
            </friction>
            <bounce/>
          </surface>
          <max_contacts>10</max_contacts>
        </collision>
        <visual name='LLowLeg_visual'>
          <pose frame=''>0 -0.0726 -0.2942 0 -0 -3.14159</pose>
          <geometry>
            <mesh>
              <scale>0.03937 -0.03937 0.03937</scale>
              <uri>model://coman_urdf/meshes/Leg3.STL</uri>
            </mesh>
          </geometry>
          <material>
            <script>
              <name>Gazebo/DarkGrey</name>
              <uri>file://media/materials/scripts/gazebo.material</uri>
            </script>
          </material>
        </visual>
        <gravity>1</gravity>
        <velocity_decay/>
        <self_collide>0</self_collide>
        <enable_wind>0</enable_wind>
        <kinematic>0</kinematic>
      </link>
      <joint name='LKneeSag' type='revolute'>
        <child>LLowLeg</child>
        <parent>LThighLowLeg</parent>
        <axis>
          <xyz>0 1 0</xyz>
          <limit>
            <lower>-0.1745</lower>
            <upper>1.9199</upper>
            <effort>50</effort>
            <velocity>4</velocity>
          </limit>
          <dynamics>
            <damping>3</damping>
            <friction>0</friction>
            <spring_reference>0</spring_reference>
            <spring_stiffness>0</spring_stiffness>
          </dynamics>
          <use_parent_model_frame>1</use_parent_model_frame>
        </axis>
        <physics>
          <provide_feedback>1</provide_feedback>
          <ode>
            <provide_feedback>1</provide_feedback>
            <implicit_spring_damper>1</implicit_spring_damper>
            <cfm_damping>1</cfm_damping>
            <limit>
              <cfm>0</cfm>
              <erp>0.2</erp>
            </limit>
          </ode>
        </physics>
      </joint>
      <link name='LFootmot'>
        <pose frame=''>0 0.0726 -0.4268 0 -0 0</pose>
        <inertial>
          <pose frame=''>0.000881 0.000922 0.00023 0 -0 0</pose>
          <mass>0.729921</mass>
          <inertia>
            <ixx>0.000320344</ixx>
            <ixy>-7.63463e-06</ixy>
            <ixz>2.54302e-07</ixz>
            <iyy>0.000365844</iyy>
            <iyz>3.68893e-06</iyz>
            <izz>0.000360652</izz>
          </inertia>
        </inertial>
        <collision name='LFootmot_collision'>
          <pose frame=''>0 -0.0726 -0.0932 0 -0 -3.14159</pose>
          <geometry>
            <mesh>
              <scale>0.03937 -0.03937 0.03937</scale>
              <uri>model://coman_urdf/meshes/simple/Leg4.STL</uri>
            </mesh>
          </geometry>
          <surface>
            <contact>
              <ode/>
            </contact>
            <friction>
              <ode/>
              <torsional>
                <ode/>
              </torsional>
            </friction>
            <bounce/>
          </surface>
          <max_contacts>10</max_contacts>
        </collision>
        <visual name='LFootmot_visual'>
          <pose frame=''>0 -0.0726 -0.0932 0 -0 -3.14159</pose>
          <geometry>
            <mesh>
              <scale>0.03937 -0.03937 0.03937</scale>
              <uri>model://coman_urdf/meshes/Leg4.STL</uri>
            </mesh>
          </geometry>
          <material>
            <script>
              <name>Gazebo/DarkGrey</name>
              <uri>file://media/materials/scripts/gazebo.material</uri>
            </script>
          </material>
        </visual>
        <gravity>1</gravity>
        <velocity_decay/>
        <self_collide>0</self_collide>
        <enable_wind>0</enable_wind>
        <kinematic>0</kinematic>
      </link>
      <joint name='LAnkLat' type='revolute'>
        <child>LFootmot</child>
        <parent>LLowLeg</parent>
        <axis>
          <xyz>1 0 0</xyz>
          <limit>
            <lower>-0.6109</lower>
            <upper>0.6109</upper>
            <effort>50</effort>
            <velocity>4</velocity>
          </limit>
          <dynamics>
            <damping>3</damping>
            <friction>0</friction>
            <spring_reference>0</spring_reference>
            <spring_stiffness>0</spring_stiffness>
          </dynamics>
          <use_parent_model_frame>1</use_parent_model_frame>
        </axis>
        <physics>
          <provide_feedback>1</provide_feedback>
          <ode>
            <provide_feedback>1</provide_feedback>
            <implicit_spring_damper>1</implicit_spring_damper>
            <cfm_damping>1</cfm_damping>
            <limit>
              <cfm>0</cfm>
              <erp>0.2</erp>
            </limit>
          </ode>
        </physics>
      </joint>
      <link name='LFoot'>
        <pose frame=''>0 0.0726 -0.4268 0 -0 0</pose>
        <inertial>
          <pose frame=''>0.009692 0.009046 -0.043062 0 -0 0</pose>
          <mass>0.666467</mass>
          <inertia>
            <ixx>0.00129448</ixx>
            <ixy>9.23877e-05</ixy>
            <ixz>0.000200801</ixz>
            <iyy>0.00158518</iyy>
            <iyz>-0.000275993</iyz>
            <izz>0.00133268</izz>
          </inertia>
        </inertial>
        <collision name='LFoot_collision'>
          <pose frame=''>0.03 0 -0.07 0 -0 0</pose>
          <geometry>
            <box>
              <size>0.2 0.1 0.04</size>
            </box>
          </geometry>
          <surface>
            <contact>
              <ode>
                <kp>1e+06</kp>
                <kd>100</kd>
                <max_vel>1</max_vel>
                <min_depth>0</min_depth>
              </ode>
            </contact>
            <friction>
              <ode>
                <mu>1</mu>
                <mu2>1</mu2>
                <fdir1>1 0 0</fdir1>
              </ode>
              <torsional>
                <ode/>
              </torsional>
            </friction>
            <bounce/>
          </surface>
          <max_contacts>10</max_contacts>
        </collision>
        <visual name='LFoot_visual'>
          <pose frame=''>0.03 0 -0.07 0 -0 0</pose>
          <geometry>
            <box>
              <size>0.2 0.1 0.04</size>
            </box>
          </geometry>
          <material>
            <script>
              <name>Gazebo/DarkGrey</name>
              <uri>file://media/materials/scripts/gazebo.material</uri>
            </script>
          </material>
        </visual>
        <velocity_decay/>
        <gravity>1</gravity>
        <velocity_decay/>
        <self_collide>0</self_collide>
        <enable_wind>0</enable_wind>
        <kinematic>0</kinematic>
      </link>
      <joint name='LAnkSag' type='revolute'>
        <child>LFoot</child>
        <parent>LFootmot</parent>
        <axis>
          <xyz>0 1 0</xyz>
          <limit>
            <lower>-1.2217</lower>
            <upper>1.2217</upper>
            <effort>50</effort>
            <velocity>4</velocity>
          </limit>
          <dynamics>
            <damping>3</damping>
            <friction>0</friction>
            <spring_reference>0</spring_reference>
            <spring_stiffness>0</spring_stiffness>
          </dynamics>
          <use_parent_model_frame>1</use_parent_model_frame>
        </axis>
        <physics>
          <provide_feedback>1</provide_feedback>
          <ode>
            <provide_feedback>1</provide_feedback>
            <implicit_spring_damper>1</implicit_spring_damper>
            <cfm_damping>1</cfm_damping>
            <limit>
              <cfm>0</cfm>
              <erp>0.2</erp>
            </limit>
          </ode>
        </physics>
        <sensor name='left_leg_ft' type='force_torque'>
          <force_torque>
            <frame>sensor</frame>
            <measure_direction>child_to_parent</measure_direction>
          </force_torque>
          <always_on>1</always_on>
          <visualize>1</visualize>
          <update_rate>1000</update_rate>
          <pose frame=''>0 0 -0.065 0 -0 0</pose>
        </sensor>
      </joint>
      <link name='RHipMot'>
        <pose frame=''>0 -0.023 0 0 -0 0</pose>
        <inertial>
          <pose frame=''>-0.000327 -0.023587 -0.000265 0 -0 0</pose>
          <mass>0.892582</mass>
          <inertia>
            <ixx>0.000476723</ixx>
            <ixy>-3.99366e-06</ixy>
            <ixz>-2.48026e-06</ixz>
            <iyy>0.000545804</iyy>
            <iyz>-3.33896e-06</iyz>
            <izz>0.000512686</izz>
          </inertia>
        </inertial>
        <collision name='RHipMot_collision'>
          <pose frame=''>0 0.023 -0.52 0 -0 -3.14159</pose>
          <geometry>
            <mesh>
              <scale>0.03937 0.03937 0.03937</scale>
              <uri>model://coman_urdf/meshes/simple/Leg0.STL</uri>
            </mesh>
          </geometry>
          <surface>
            <contact>
              <ode/>
            </contact>
            <friction>
              <ode/>
              <torsional>
                <ode/>
              </torsional>
            </friction>
            <bounce/>
          </surface>
          <max_contacts>10</max_contacts>
        </collision>
        <visual name='RHipMot_visual'>
          <pose frame=''>0 0.023 -0.52 0 -0 -3.14159</pose>
          <geometry>
            <mesh>
              <scale>0.03937 0.03937 0.03937</scale>
              <uri>model://coman_urdf/meshes/Leg0.STL</uri>
            </mesh>
          </geometry>
          <material>
            <script>
              <name>Gazebo/DarkGrey</name>
              <uri>file://media/materials/scripts/gazebo.material</uri>
            </script>
          </material>
        </visual>
        <gravity>1</gravity>
        <velocity_decay/>
        <self_collide>0</self_collide>
        <enable_wind>0</enable_wind>
        <kinematic>0</kinematic>
      </link>
      <joint name='RHipSag' type='revolute'>
        <child>RHipMot</child>
        <parent>base_link</parent>
        <axis>
          <xyz>0 1 0</xyz>
          <limit>
            <lower>-1.9199</lower>
            <upper>0.7854</upper>
            <effort>50</effort>
            <velocity>4</velocity>
          </limit>
          <dynamics>
            <damping>3</damping>
            <friction>0</friction>
            <spring_reference>0</spring_reference>
            <spring_stiffness>0</spring_stiffness>
          </dynamics>
          <use_parent_model_frame>1</use_parent_model_frame>
        </axis>
        <physics>
          <provide_feedback>1</provide_feedback>
          <ode>
            <provide_feedback>1</provide_feedback>
            <implicit_spring_damper>1</implicit_spring_damper>
            <cfm_damping>1</cfm_damping>
            <limit>
              <cfm>0</cfm>
              <erp>0.2</erp>
            </limit>
          </ode>
        </physics>
      </joint>
      <link name='RThighUpLeg'>
        <pose frame=''>0 -0.0726 0 0 -0 0</pose>
        <inertial>
          <pose frame=''>0.001259 -0.016896 -0.058903 0 -0 0</pose>
          <mass>1.02461</mass>
          <inertia>
            <ixx>0.000916572</ixx>
            <ixy>-1.44499e-06</ixy>
            <ixz>-1.6685e-05</ixz>
            <iyy>0.0010485</iyy>
            <iyz>2.54929e-05</iyz>
            <izz>0.000686372</izz>
          </inertia>
        </inertial>
        <collision name='RThighUpLeg_collision'>
          <pose frame=''>0 0.0726 -0.52 0 -0 -3.14159</pose>
          <geometry>
            <mesh>
              <scale>0.03937 0.03937 0.03937</scale>
              <uri>model://coman_urdf/meshes/simple/Leg1.STL</uri>
            </mesh>
          </geometry>
          <surface>
            <contact>
              <ode/>
            </contact>
            <friction>
              <ode/>
              <torsional>
                <ode/>
              </torsional>
            </friction>
            <bounce/>
          </surface>
          <max_contacts>10</max_contacts>
        </collision>
        <visual name='RThighUpLeg_visual'>
          <pose frame=''>0 0.0726 -0.52 0 -0 -3.14159</pose>
          <geometry>
            <mesh>
              <scale>0.03937 0.03937 0.03937</scale>
              <uri>model://coman_urdf/meshes/Leg1.STL</uri>
            </mesh>
          </geometry>
          <material>
            <script>
              <name>Gazebo/DarkGrey</name>
              <uri>file://media/materials/scripts/gazebo.material</uri>
            </script>
          </material>
        </visual>
        <gravity>1</gravity>
        <velocity_decay/>
        <self_collide>0</self_collide>
        <enable_wind>0</enable_wind>
        <kinematic>0</kinematic>
      </link>
      <joint name='RHipLat' type='revolute'>
        <child>RThighUpLeg</child>
        <parent>RHipMot</parent>
        <axis>
          <xyz>1 0 0</xyz>
          <limit>
            <lower>-1.0472</lower>
            <upper>0.4363</upper>
            <effort>50</effort>
            <velocity>4</velocity>
          </limit>
          <dynamics>
            <damping>3</damping>
            <friction>0</friction>
            <spring_reference>0</spring_reference>
            <spring_stiffness>0</spring_stiffness>
          </dynamics>
          <use_parent_model_frame>1</use_parent_model_frame>
        </axis>
        <physics>
          <provide_feedback>1</provide_feedback>
          <ode>
            <provide_feedback>1</provide_feedback>
            <implicit_spring_damper>1</implicit_spring_damper>
            <cfm_damping>1</cfm_damping>
            <limit>
              <cfm>0</cfm>
              <erp>0.2</erp>
            </limit>
          </ode>
        </physics>
      </joint>
      <link name='RThighLowLeg'>
        <pose frame=''>0 -0.0726 -0.1024 0 -0 0</pose>
        <inertial>
          <pose frame=''>0.000987 0.00067 -0.075717 0 -0 0</pose>
          <mass>1.70011</mass>
          <inertia>
            <ixx>0.00389795</ixx>
            <ixy>1.78024e-06</ixy>
            <ixz>2.64033e-05</ixz>
            <iyy>0.00393608</iyy>
            <iyz>4.52271e-05</iyz>
            <izz>0.000902187</izz>
          </inertia>
        </inertial>
        <collision name='RThighLowLeg_collision'>
          <pose frame=''>0 0.0726 -0.4176 0 -0 -3.14159</pose>
          <geometry>
            <mesh>
              <scale>0.03937 0.03937 0.03937</scale>
              <uri>model://coman_urdf/meshes/simple/Leg2.STL</uri>
            </mesh>
          </geometry>
          <surface>
            <contact>
              <ode/>
            </contact>
            <friction>
              <ode/>
              <torsional>
                <ode/>
              </torsional>
            </friction>
            <bounce/>
          </surface>
          <max_contacts>10</max_contacts>
        </collision>
        <visual name='RThighLowLeg_visual'>
          <pose frame=''>0 0.0726 -0.4176 0 -0 -3.14159</pose>
          <geometry>
            <mesh>
              <scale>0.03937 0.03937 0.03937</scale>
              <uri>model://coman_urdf/meshes/Leg2.STL</uri>
            </mesh>
          </geometry>
          <material>
            <script>
              <name>Gazebo/DarkGrey</name>
              <uri>file://media/materials/scripts/gazebo.material</uri>
            </script>
          </material>
        </visual>
        <gravity>1</gravity>
        <velocity_decay/>
        <self_collide>0</self_collide>
        <enable_wind>0</enable_wind>
        <kinematic>0</kinematic>
      </link>
      <joint name='RHipYaw' type='revolute'>
        <child>RThighLowLeg</child>
        <parent>RThighUpLeg</parent>
        <axis>
          <xyz>0 0 1</xyz>
          <limit>
            <lower>-0.8727</lower>
            <upper>0.8727</upper>
            <effort>50</effort>
            <velocity>4</velocity>
          </limit>
          <dynamics>
            <damping>3</damping>
            <friction>0</friction>
            <spring_reference>0</spring_reference>
            <spring_stiffness>0</spring_stiffness>
          </dynamics>
          <use_parent_model_frame>1</use_parent_model_frame>
        </axis>
        <physics>
          <provide_feedback>1</provide_feedback>
          <ode>
            <provide_feedback>1</provide_feedback>
            <implicit_spring_damper>1</implicit_spring_damper>
            <cfm_damping>1</cfm_damping>
            <limit>
              <cfm>0</cfm>
              <erp>0.2</erp>
            </limit>
          </ode>
        </physics>
      </joint>
      <link name='RLowLeg'>
        <pose frame=''>0 -0.0726 -0.2258 0 -0 0</pose>
        <inertial>
          <pose frame=''>0.002461 -0.00531 -0.08599 0 -0 0</pose>
          <mass>1.40982</mass>
          <inertia>
            <ixx>0.0040604</ixx>
            <ixy>1.12272e-05</ixy>
            <ixz>1.2261e-05</ixz>
            <iyy>0.00400565</iyy>
            <iyz>0.000518992</iyz>
            <izz>0.00124141</izz>
          </inertia>
        </inertial>
        <collision name='RLowLeg_collision'>
          <pose frame=''>0 0.0726 -0.2942 0 -0 -3.14159</pose>
          <geometry>
            <mesh>
              <scale>0.03937 0.03937 0.03937</scale>
              <uri>model://coman_urdf/meshes/simple/Leg3.STL</uri>
            </mesh>
          </geometry>
          <surface>
            <contact>
              <ode/>
            </contact>
            <friction>
              <ode/>
              <torsional>
                <ode/>
              </torsional>
            </friction>
            <bounce/>
          </surface>
          <max_contacts>10</max_contacts>
        </collision>
        <visual name='RLowLeg_visual'>
          <pose frame=''>0 0.0726 -0.2942 0 -0 -3.14159</pose>
          <geometry>
            <mesh>
              <scale>0.03937 0.03937 0.03937</scale>
              <uri>model://coman_urdf/meshes/Leg3.STL</uri>
            </mesh>
          </geometry>
          <material>
            <script>
              <name>Gazebo/DarkGrey</name>
              <uri>file://media/materials/scripts/gazebo.material</uri>
            </script>
          </material>
        </visual>
        <gravity>1</gravity>
        <velocity_decay/>
        <self_collide>0</self_collide>
        <enable_wind>0</enable_wind>
        <kinematic>0</kinematic>
      </link>
      <joint name='RKneeSag' type='revolute'>
        <child>RLowLeg</child>
        <parent>RThighLowLeg</parent>
        <axis>
          <xyz>0 1 0</xyz>
          <limit>
            <lower>-0.1745</lower>
            <upper>1.9199</upper>
            <effort>50</effort>
            <velocity>4</velocity>
          </limit>
          <dynamics>
            <damping>3</damping>
            <friction>0</friction>
            <spring_reference>0</spring_reference>
            <spring_stiffness>0</spring_stiffness>
          </dynamics>
          <use_parent_model_frame>1</use_parent_model_frame>
        </axis>
        <physics>
          <provide_feedback>1</provide_feedback>
          <ode>
            <provide_feedback>1</provide_feedback>
            <implicit_spring_damper>1</implicit_spring_damper>
            <cfm_damping>1</cfm_damping>
            <limit>
              <cfm>0</cfm>
              <erp>0.2</erp>
            </limit>
          </ode>
        </physics>
      </joint>
      <link name='RFootmot'>
        <pose frame=''>0 -0.0726 -0.4268 0 -0 0</pose>
        <inertial>
          <pose frame=''>0.000881 -0.000922 0.00023 0 -0 0</pose>
          <mass>0.729921</mass>
          <inertia>
            <ixx>0.000320344</ixx>
            <ixy>7.63463e-06</ixy>
            <ixz>2.54302e-07</ixz>
            <iyy>0.000365844</iyy>
            <iyz>-3.68893e-06</iyz>
            <izz>0.000360652</izz>
          </inertia>
        </inertial>
        <collision name='RFootmot_collision'>
          <pose frame=''>0 0.0726 -0.0932 0 -0 -3.14159</pose>
          <geometry>
            <mesh>
              <scale>0.03937 0.03937 0.03937</scale>
              <uri>model://coman_urdf/meshes/simple/Leg4.STL</uri>
            </mesh>
          </geometry>
          <surface>
            <contact>
              <ode/>
            </contact>
            <friction>
              <ode/>
              <torsional>
                <ode/>
              </torsional>
            </friction>
            <bounce/>
          </surface>
          <max_contacts>10</max_contacts>
        </collision>
        <visual name='RFootmot_visual'>
          <pose frame=''>0 0.0726 -0.0932 0 -0 -3.14159</pose>
          <geometry>
            <mesh>
              <scale>0.03937 0.03937 0.03937</scale>
              <uri>model://coman_urdf/meshes/Leg4.STL</uri>
            </mesh>
          </geometry>
          <material>
            <script>
              <name>Gazebo/DarkGrey</name>
              <uri>file://media/materials/scripts/gazebo.material</uri>
            </script>
          </material>
        </visual>
        <gravity>1</gravity>
        <velocity_decay/>
        <self_collide>0</self_collide>
        <enable_wind>0</enable_wind>
        <kinematic>0</kinematic>
      </link>
      <joint name='RAnkLat' type='revolute'>
        <child>RFootmot</child>
        <parent>RLowLeg</parent>
        <axis>
          <xyz>1 0 0</xyz>
          <limit>
            <lower>-0.6109</lower>
            <upper>0.6109</upper>
            <effort>50</effort>
            <velocity>4</velocity>
          </limit>
          <dynamics>
            <damping>3</damping>
            <friction>0</friction>
            <spring_reference>0</spring_reference>
            <spring_stiffness>0</spring_stiffness>
          </dynamics>
          <use_parent_model_frame>1</use_parent_model_frame>
        </axis>
        <physics>
          <provide_feedback>1</provide_feedback>
          <ode>
            <provide_feedback>1</provide_feedback>
            <implicit_spring_damper>1</implicit_spring_damper>
            <cfm_damping>1</cfm_damping>
            <limit>
              <cfm>0</cfm>
              <erp>0.2</erp>
            </limit>
          </ode>
        </physics>
      </joint>
      <link name='RFoot'>
        <pose frame=''>0 -0.0726 -0.4268 0 -0 0</pose>
        <inertial>
          <pose frame=''>0.009692 -0.009046 -0.043062 0 -0 0</pose>
          <mass>0.666467</mass>
          <inertia>
            <ixx>0.00129448</ixx>
            <ixy>-9.23877e-05</ixy>
            <ixz>0.000200801</ixz>
            <iyy>0.00158518</iyy>
            <iyz>0.000275993</iyz>
            <izz>0.00133268</izz>
          </inertia>
        </inertial>
        <collision name='RFoot_collision'>
          <pose frame=''>0.03 0 -0.07 0 -0 0</pose>
          <geometry>
            <box>
              <size>0.2 0.1 0.04</size>
            </box>
          </geometry>
          <surface>
            <contact>
              <ode>
                <kp>1e+06</kp>
                <kd>100</kd>
                <max_vel>1</max_vel>
                <min_depth>0</min_depth>
              </ode>
            </contact>
            <friction>
              <ode>
                <mu>1</mu>
                <mu2>1</mu2>
                <fdir1>1 0 0</fdir1>
              </ode>
              <torsional>
                <ode/>
              </torsional>
            </friction>
            <bounce/>
          </surface>
          <max_contacts>10</max_contacts>
        </collision>
        <visual name='RFoot_visual'>
          <pose frame=''>0.03 0 -0.07 0 -0 0</pose>
          <geometry>
            <box>
              <size>0.2 0.1 0.04</size>
            </box>
          </geometry>
          <material>
            <script>
              <name>Gazebo/DarkGrey</name>
              <uri>file://media/materials/scripts/gazebo.material</uri>
            </script>
          </material>
        </visual>
        <velocity_decay/>
        <gravity>1</gravity>
        <velocity_decay/>
        <self_collide>0</self_collide>
        <enable_wind>0</enable_wind>
        <kinematic>0</kinematic>
      </link>
      <joint name='RAnkSag' type='revolute'>
        <child>RFoot</child>
        <parent>RFootmot</parent>
        <axis>
          <xyz>0 1 0</xyz>
          <limit>
            <lower>-1.2217</lower>
            <upper>1.2217</upper>
            <effort>50</effort>
            <velocity>4</velocity>
          </limit>
          <dynamics>
            <damping>3</damping>
            <friction>0</friction>
            <spring_reference>0</spring_reference>
            <spring_stiffness>0</spring_stiffness>
          </dynamics>
          <use_parent_model_frame>1</use_parent_model_frame>
        </axis>
        <physics>
          <provide_feedback>1</provide_feedback>
          <ode>
            <provide_feedback>1</provide_feedback>
            <implicit_spring_damper>1</implicit_spring_damper>
            <cfm_damping>1</cfm_damping>
            <limit>
              <cfm>0</cfm>
              <erp>0.2</erp>
            </limit>
          </ode>
        </physics>
        <sensor name='right_leg_ft' type='force_torque'>
          <force_torque>
            <frame>sensor</frame>
            <measure_direction>child_to_parent</measure_direction>
          </force_torque>
          <always_on>1</always_on>
          <visualize>1</visualize>
          <update_rate>1000</update_rate>
          <pose frame=''>0 0 -0.065 0 -0 0</pose>
        </sensor>
      </joint>
      <link name='DWL'>
        <pose frame=''>0.020282 0 0.119121 0 -0 0</pose>
        <inertial>
          <pose frame=''>0.00043 -0.009765 0.033011 0 -0 0</pose>
          <mass>0.545888</mass>
          <inertia>
            <ixx>0.000971266</ixx>
            <ixy>-7.21012e-07</ixy>
            <ixz>1.14401e-06</ixz>
            <iyy>0.000746867</iyy>
            <iyz>-0.000174509</iyz>
            <izz>0.000621962</izz>
          </inertia>
        </inertial>
        <collision name='DWL_collision'>
          <pose frame=''>-0.020282 0 -0.639121 0 -0 -3.14159</pose>
          <geometry>
            <mesh>
              <scale>0.03937 0.03937 0.03937</scale>
              <uri>model://coman_urdf/meshes/simple/Torso1.STL</uri>
            </mesh>
          </geometry>
          <surface>
            <contact>
              <ode/>
            </contact>
            <friction>
              <ode/>
              <torsional>
                <ode/>
              </torsional>
            </friction>
            <bounce/>
          </surface>
          <max_contacts>10</max_contacts>
        </collision>
        <visual name='DWL_visual'>
          <pose frame=''>-0.020282 0 -0.639121 0 -0 -3.14159</pose>
          <geometry>
            <mesh>
              <scale>0.03937 0.03937 0.03937</scale>
              <uri>model://coman_urdf/meshes/Torso1.STL</uri>
            </mesh>
          </geometry>
          <material>
            <script>
              <name>Gazebo/DarkGrey</name>
              <uri>file://media/materials/scripts/gazebo.material</uri>
            </script>
          </material>
        </visual>
        <gravity>1</gravity>
        <velocity_decay/>
        <self_collide>0</self_collide>
        <enable_wind>0</enable_wind>
        <kinematic>0</kinematic>
      </link>
      <joint name='WaistLat' type='revolute'>
        <child>DWL</child>
        <parent>base_link</parent>
        <axis>
          <xyz>0.939693 0 0.34202</xyz>
          <limit>
            <lower>-0.5236</lower>
            <upper>0.5235</upper>
            <effort>50</effort>
            <velocity>4</velocity>
          </limit>
          <dynamics>
            <damping>3</damping>
            <friction>0</friction>
            <spring_reference>0</spring_reference>
            <spring_stiffness>0</spring_stiffness>
          </dynamics>
          <use_parent_model_frame>1</use_parent_model_frame>
        </axis>
        <physics>
          <provide_feedback>1</provide_feedback>
          <ode>
            <provide_feedback>1</provide_feedback>
            <implicit_spring_damper>1</implicit_spring_damper>
            <cfm_damping>1</cfm_damping>
            <limit>
              <cfm>0</cfm>
              <erp>0.2</erp>
            </limit>
          </ode>
        </physics>
      </joint>
      <link name='DWS'>
        <pose frame=''>0.020282 0 0.119121 0 -0 0</pose>
        <inertial>
          <pose frame=''>-0.002127 0.003358 -0.001008 0 -0 0</pose>
          <mass>0.753984</mass>
          <inertia>
            <ixx>0.000340933</ixx>
            <ixy>-6.212e-06</ixy>
            <ixz>-1.38635e-06</ixz>
            <iyy>0.000395819</iyy>
            <iyz>1.44302e-06</iyz>
            <izz>0.000374498</izz>
          </inertia>
        </inertial>
        <collision name='DWS_collision'>
          <pose frame=''>-0.020282 0 -0.639121 0 -0 -3.14159</pose>
          <geometry>
            <mesh>
              <scale>0.03937 0.03937 0.03937</scale>
              <uri>model://coman_urdf/meshes/simple/Torso2.STL</uri>
            </mesh>
          </geometry>
          <surface>
            <contact>
              <ode/>
            </contact>
            <friction>
              <ode/>
              <torsional>
                <ode/>
              </torsional>
            </friction>
            <bounce/>
          </surface>
          <max_contacts>10</max_contacts>
        </collision>
        <visual name='DWS_visual'>
          <pose frame=''>-0.020282 0 -0.639121 0 -0 -3.14159</pose>
          <geometry>
            <mesh>
              <scale>0.03937 0.03937 0.03937</scale>
              <uri>model://coman_urdf/meshes/Torso2.STL</uri>
            </mesh>
          </geometry>
          <material>
            <script>
              <name>Gazebo/DarkGrey</name>
              <uri>file://media/materials/scripts/gazebo.material</uri>
            </script>
          </material>
        </visual>
        <gravity>1</gravity>
        <velocity_decay/>
        <self_collide>0</self_collide>
        <enable_wind>0</enable_wind>
        <kinematic>0</kinematic>
      </link>
      <joint name='WaistSag' type='revolute'>
        <child>DWS</child>
        <parent>DWL</parent>
        <axis>
          <xyz>0 1 0</xyz>
          <limit>
            <lower>-0.3491</lower>
            <upper>0.8727</upper>
            <effort>50</effort>
            <velocity>4</velocity>
          </limit>
          <dynamics>
            <damping>3</damping>
            <friction>0</friction>
            <spring_reference>0</spring_reference>
            <spring_stiffness>0</spring_stiffness>
          </dynamics>
          <use_parent_model_frame>1</use_parent_model_frame>
        </axis>
        <physics>
          <provide_feedback>1</provide_feedback>
          <ode>
            <provide_feedback>1</provide_feedback>
            <implicit_spring_damper>1</implicit_spring_damper>
            <cfm_damping>1</cfm_damping>
            <limit>
              <cfm>0</cfm>
              <erp>0.2</erp>
            </limit>
          </ode>
        </physics>
      </joint>
      <link name='DWYTorso'>
        <pose frame=''>0.020282 0 0.166621 0 -0 0</pose>
        <inertial>
          <pose frame=''>-0.028128 1.7e-05 0.147671 0 -0 0</pose>
          <mass>6.95172</mass>
          <inertia>
            <ixx>0.118619</ixx>
            <ixy>-8.59855e-06</ixy>
            <ixz>-0.0191304</ixz>
            <iyy>0.117743</iyy>
            <iyz>1.17175e-05</iyz>
            <izz>0.0308825</izz>
          </inertia>
        </inertial>
        <collision name='DWYTorso_collision'>
          <pose frame=''>-0.020282 0 -0.686621 0 -0 -3.14159</pose>
          <geometry>
            <mesh>
              <scale>0.03937 0.03937 0.03937</scale>
              <uri>model://coman_urdf/meshes/simple/Torso3.STL</uri>
            </mesh>
          </geometry>
          <surface>
            <contact>
              <ode/>
            </contact>
            <friction>
              <ode/>
              <torsional>
                <ode/>
              </torsional>
            </friction>
            <bounce/>
          </surface>
          <max_contacts>10</max_contacts>
        </collision>
        <collision name='DWYTorso_fixed_joint_lump__Xtion_body_collision_1'>
          <pose frame=''>-0.020282 0 -0.686621 0 -0 -3.14159</pose>
          <geometry>
            <mesh>
              <scale>0.03937 0.03937 0.03937</scale>
              <uri>model://coman_urdf/meshes/simple/XtionBase.STL</uri>
            </mesh>
          </geometry>
          <surface>
            <contact>
              <ode/>
            </contact>
            <friction>
              <ode/>
              <torsional>
                <ode/>
              </torsional>
            </friction>
            <bounce/>
          </surface>
          <max_contacts>10</max_contacts>
        </collision>
        <collision name='DWYTorso_fixed_joint_lump__Xtion_cam_body_collision_2'>
          <pose frame=''>-0.0205 0 -0.6868 0 -0 -3.14159</pose>
          <geometry>
            <mesh>
              <scale>0.001 0.001 0.001</scale>
              <uri>model://coman_urdf/meshes/simple/XtionCamBody.STL</uri>
            </mesh>
          </geometry>
          <surface>
            <contact>
              <ode/>
            </contact>
            <friction>
              <ode/>
              <torsional>
                <ode/>
              </torsional>
            </friction>
            <bounce/>
          </surface>
          <max_contacts>10</max_contacts>
        </collision>
        <visual name='DWYTorso_visual'>
          <pose frame=''>-0.020282 0 -0.686621 0 -0 -3.14159</pose>
          <geometry>
            <mesh>
              <scale>0.03937 0.03937 0.03937</scale>
              <uri>model://coman_urdf/meshes/Torso3.STL</uri>
            </mesh>
          </geometry>
          <material>
            <script>
              <name>Gazebo/Red</name>
              <uri>file://media/materials/scripts/gazebo.material</uri>
            </script>
          </material>
        </visual>
        <visual name='DWYTorso_fixed_joint_lump__Xtion_body_visual_1'>
          <pose frame=''>-0.020282 0 -0.686621 0 -0 -3.14159</pose>
          <geometry>
            <mesh>
              <scale>0.03937 0.03937 0.03937</scale>
              <uri>model://coman_urdf/meshes/XtionBase.STL</uri>
            </mesh>
          </geometry>
          <material>
            <script>
              <name>Gazebo/DarkGrey</name>
              <uri>file://media/materials/scripts/gazebo.material</uri>
            </script>
          </material>
        </visual>
        <visual name='DWYTorso_fixed_joint_lump__Xtion_cam_body_visual_2'>
          <pose frame=''>-0.0205 0 -0.6868 0 -0 -3.14159</pose>
          <geometry>
            <mesh>
              <scale>0.001 0.001 0.001</scale>
              <uri>model://coman_urdf/meshes/XtionCamBody.STL</uri>
            </mesh>
          </geometry>
          <material>
            <script>
              <name>Gazebo/Grey</name>
              <uri>file://media/materials/scripts/gazebo.material</uri>
            </script>
          </material>
        </visual>
        <velocity_decay/>
        <velocity_decay/>
        <velocity_decay/>
        <sensor name='openni_camera_camera' type='depth'>
          <always_on>1</always_on>
          <visualize>1</visualize>
          <camera name='__default__'>
            <horizontal_fov>1.047</horizontal_fov>
            <image>
              <width>640</width>
              <height>480</height>
              <format>R8G8B8</format>
            </image>
            <depth_camera>
              <output>depths</output>
            </depth_camera>
            <clip>
              <near>0.1</near>
              <far>100</far>
            </clip>
          </camera>
          <plugin name='camera_controller' filename='libgazebo_ros_openni_kinect.so'>
            <alwaysOn>1</alwaysOn>
            <updateRate>10.0</updateRate>
            <cameraName>camera</cameraName>
            <frameName>camera_link</frameName>
            <imageTopicName>rgb/image_raw</imageTopicName>
            <depthImageTopicName>depth/image_raw</depthImageTopicName>
            <pointCloudTopicName>depth/points</pointCloudTopicName>
            <cameraInfoTopicName>rgb/camera_info</cameraInfoTopicName>
            <depthImageCameraInfoTopicName>depth/camera_info</depthImageCameraInfoTopicName>
            <pointCloudCutoff>0.4</pointCloudCutoff>
            <hackBaseline>0.07</hackBaseline>
            <distortionK1>0.0</distortionK1>
            <distortionK2>0.0</distortionK2>
            <distortionK3>0.0</distortionK3>
            <distortionT1>0.0</distortionT1>
            <distortionT2>0.0</distortionT2>
            <CxPrime>0.0</CxPrime>
            <Cx>0.0</Cx>
            <Cy>0.0</Cy>
            <focalLength>0.0</focalLength>
          </plugin>
          <pose frame=''>0.071 0 0.591 0 -0 0</pose>
        </sensor>
        <gravity>1</gravity>
        <velocity_decay/>
        <self_collide>0</self_collide>
        <enable_wind>0</enable_wind>
        <kinematic>0</kinematic>
      </link>
      <joint name='WaistYaw' type='revolute'>
        <child>DWYTorso</child>
        <parent>DWS</parent>
        <axis>
          <xyz>0 0 1</xyz>
          <limit>
            <lower>-1.3963</lower>
            <upper>1.3962</upper>
            <effort>50</effort>
            <velocity>4</velocity>
          </limit>
          <dynamics>
            <damping>3</damping>
            <friction>0</friction>
            <spring_reference>0</spring_reference>
            <spring_stiffness>0</spring_stiffness>
          </dynamics>
          <use_parent_model_frame>1</use_parent_model_frame>
        </axis>
        <physics>
          <provide_feedback>1</provide_feedback>
          <ode>
            <provide_feedback>1</provide_feedback>
            <implicit_spring_damper>1</implicit_spring_damper>
            <cfm_damping>1</cfm_damping>
            <limit>
              <cfm>0</cfm>
              <erp>0.2</erp>
            </limit>
          </ode>
        </physics>
      </joint>
      <link name='LShp'>
        <pose frame=''>0.005305 0.0825 0.324329 0 -0 0</pose>
        <inertial>
          <pose frame=''>0.00995 0.038682 0.000164 0 -0 0</pose>
          <mass>0.567822</mass>
          <inertia>
            <ixx>0.000783375</ixx>
            <ixy>-0.000190358</ixy>
            <ixz>-3.00377e-06</ixz>
            <iyy>0.000633999</iyy>
            <iyz>-4.38408e-06</iyz>
            <izz>0.00100805</izz>
          </inertia>
        </inertial>
        <collision name='LShp_collision'>
          <pose frame=''>-0.005305 -0.0825 -0.844329 0 -0 -3.14159</pose>
          <geometry>
            <mesh>
              <scale>0.03937 -0.03937 0.03937</scale>
              <uri>model://coman_urdf/meshes/simple/Arm0.STL</uri>
            </mesh>
          </geometry>
          <surface>
            <contact>
              <ode/>
            </contact>
            <friction>
              <ode/>
              <torsional>
                <ode/>
              </torsional>
            </friction>
            <bounce/>
          </surface>
          <max_contacts>10</max_contacts>
        </collision>
        <visual name='LShp_visual'>
          <pose frame=''>-0.005305 -0.0825 -0.844329 0 -0 -3.14159</pose>
          <geometry>
            <mesh>
              <scale>0.03937 -0.03937 0.03937</scale>
              <uri>model://coman_urdf/meshes/Arm0.STL</uri>
            </mesh>
          </geometry>
          <material>
            <script>
              <name>Gazebo/DarkGrey</name>
              <uri>file://media/materials/scripts/gazebo.material</uri>
            </script>
          </material>
        </visual>
        <gravity>1</gravity>
        <velocity_decay/>
        <self_collide>0</self_collide>
        <enable_wind>0</enable_wind>
        <kinematic>0</kinematic>
      </link>
      <joint name='LShSag' type='revolute'>
        <child>LShp</child>
        <parent>DWYTorso</parent>
        <axis>
          <xyz>0 1 0</xyz>
          <limit>
            <lower>-3.4034</lower>
            <upper>1.6581</upper>
            <effort>50</effort>
            <velocity>4</velocity>
          </limit>
          <dynamics>
            <damping>3</damping>
            <friction>0</friction>
            <spring_reference>0</spring_reference>
            <spring_stiffness>0</spring_stiffness>
          </dynamics>
          <use_parent_model_frame>1</use_parent_model_frame>
        </axis>
        <physics>
          <provide_feedback>1</provide_feedback>
          <ode>
            <provide_feedback>1</provide_feedback>
            <implicit_spring_damper>1</implicit_spring_damper>
            <cfm_damping>1</cfm_damping>
            <limit>
              <cfm>0</cfm>
              <erp>0.2</erp>
            </limit>
          </ode>
        </physics>
      </joint>
      <link name='LShr'>
        <pose frame=''>0.005305 0.1558 0.324329 0 -0 0</pose>
        <inertial>
          <pose frame=''>-0.003894 -2e-06 -0.004862 0 -0 0</pose>
          <mass>0.776838</mass>
          <inertia>
            <ixx>0.000458129</ixx>
            <ixy>2.41111e-07</ixy>
            <ixz>9.25212e-06</ixz>
            <iyy>0.000430892</iyy>
            <iyz>4.7217e-07</iyz>
            <izz>0.000341749</izz>
          </inertia>
        </inertial>
        <collision name='LShr_collision'>
          <pose frame=''>-0.005305 -0.1558 -0.844329 0 -0 -3.14159</pose>
          <geometry>
            <mesh>
              <scale>0.03937 -0.03937 0.03937</scale>
              <uri>model://coman_urdf/meshes/simple/Arm1.STL</uri>
            </mesh>
          </geometry>
          <surface>
            <contact>
              <ode/>
            </contact>
            <friction>
              <ode/>
              <torsional>
                <ode/>
              </torsional>
            </friction>
            <bounce/>
          </surface>
          <max_contacts>10</max_contacts>
        </collision>
        <visual name='LShr_visual'>
          <pose frame=''>-0.005305 -0.1558 -0.844329 0 -0 -3.14159</pose>
          <geometry>
            <mesh>
              <scale>0.03937 -0.03937 0.03937</scale>
              <uri>model://coman_urdf/meshes/Arm1.STL</uri>
            </mesh>
          </geometry>
          <material>
            <script>
              <name>Gazebo/DarkGrey</name>
              <uri>file://media/materials/scripts/gazebo.material</uri>
            </script>
          </material>
        </visual>
        <gravity>1</gravity>
        <velocity_decay/>
        <self_collide>0</self_collide>
        <enable_wind>0</enable_wind>
        <kinematic>0</kinematic>
      </link>
      <joint name='LShLat' type='revolute'>
        <child>LShr</child>
        <parent>LShp</parent>
        <axis>
          <xyz>1 0 0</xyz>
          <limit>
            <lower>-0.31415</lower>
            <upper>2.094</upper>
            <effort>50</effort>
            <velocity>4</velocity>
          </limit>
          <dynamics>
            <damping>3</damping>
            <friction>0</friction>
            <spring_reference>0</spring_reference>
            <spring_stiffness>0</spring_stiffness>
          </dynamics>
          <use_parent_model_frame>1</use_parent_model_frame>
        </axis>
        <physics>
          <provide_feedback>1</provide_feedback>
          <ode>
            <provide_feedback>1</provide_feedback>
            <implicit_spring_damper>1</implicit_spring_damper>
            <cfm_damping>1</cfm_damping>
            <limit>
              <cfm>0</cfm>
              <erp>0.2</erp>
            </limit>
          </ode>
        </physics>
      </joint>
      <link name='LShy'>
        <pose frame=''>0.005305 0.1558 0.279521 0 -0 0</pose>
        <inertial>
          <pose frame=''>0.002271 0.007109 -0.057455 0 -0 0</pose>
          <mass>1.04623</mass>
          <inertia>
            <ixx>0.00309346</ixx>
            <ixy>-6.67028e-05</ixy>
            <ixz>0.000302223</ixz>
            <iyy>0.00291816</iyy>
            <iyz>0.000526637</iyz>
            <izz>0.000808304</izz>
          </inertia>
        </inertial>
        <collision name='LShy_collision'>
          <pose frame=''>-0.005305 -0.1558 -0.799521 0 -0 -3.14159</pose>
          <geometry>
            <mesh>
              <scale>0.03937 -0.03937 0.03937</scale>
              <uri>model://coman_urdf/meshes/simple/Arm2.STL</uri>
            </mesh>
          </geometry>
          <surface>
            <contact>
              <ode/>
            </contact>
            <friction>
              <ode/>
              <torsional>
                <ode/>
              </torsional>
            </friction>
            <bounce/>
          </surface>
          <max_contacts>10</max_contacts>
        </collision>
        <visual name='LShy_visual'>
          <pose frame=''>-0.005305 -0.1558 -0.799521 0 -0 -3.14159</pose>
          <geometry>
            <mesh>
              <scale>0.03937 -0.03937 0.03937</scale>
              <uri>model://coman_urdf/meshes/Arm2.STL</uri>
            </mesh>
          </geometry>
          <material>
            <script>
              <name>Gazebo/DarkGrey</name>
              <uri>file://media/materials/scripts/gazebo.material</uri>
            </script>
          </material>
        </visual>
        <gravity>1</gravity>
        <velocity_decay/>
        <self_collide>0</self_collide>
        <enable_wind>0</enable_wind>
        <kinematic>0</kinematic>
      </link>
      <joint name='LShYaw' type='revolute'>
        <child>LShy</child>
        <parent>LShr</parent>
        <axis>
          <xyz>0 0 1</xyz>
          <limit>
            <lower>-1.5708</lower>
            <upper>1.5708</upper>
            <effort>50</effort>
            <velocity>4</velocity>
          </limit>
          <dynamics>
            <damping>3</damping>
            <friction>0</friction>
            <spring_reference>0</spring_reference>
            <spring_stiffness>0</spring_stiffness>
          </dynamics>
          <use_parent_model_frame>1</use_parent_model_frame>
        </axis>
        <physics>
          <provide_feedback>1</provide_feedback>
          <ode>
            <provide_feedback>1</provide_feedback>
            <implicit_spring_damper>1</implicit_spring_damper>
            <cfm_damping>1</cfm_damping>
            <limit>
              <cfm>0</cfm>
              <erp>0.2</erp>
            </limit>
          </ode>
        </physics>
      </joint>
      <link name='LElb'>
        <pose frame=''>0.020305 0.1558 0.144329 0 -0 0</pose>
        <inertial>
          <pose frame=''>-0.000656 0.000935 -0.000931 0 -0 0</pose>
          <mass>0.633069</mass>
          <inertia>
            <ixx>0.000225991</ixx>
            <ixy>2.63765e-07</ixy>
            <ixz>-9.80073e-06</ixz>
            <iyy>0.000277813</iyy>
            <iyz>2.04353e-06</iyz>
            <izz>0.00021879</izz>
          </inertia>
        </inertial>
        <collision name='LElb_collision'>
          <pose frame=''>0 0 0 3.14159 1.57079 -1.57079</pose>
          <geometry>
            <mesh>
              <scale>1 1 1</scale>
              <uri>model://coman_urdf/meshes/simple/Elbow.STL</uri>
            </mesh>
          </geometry>
          <surface>
            <contact>
              <ode/>
            </contact>
            <friction>
              <ode/>
              <torsional>
                <ode/>
              </torsional>
            </friction>
            <bounce/>
          </surface>
          <max_contacts>10</max_contacts>
        </collision>
        <visual name='LElb_visual'>
          <pose frame=''>0 0 0 3.14159 1.57079 -1.57079</pose>
          <geometry>
            <mesh>
              <scale>1 1 1</scale>
              <uri>model://coman_urdf/meshes/Elbow.STL</uri>
            </mesh>
          </geometry>
          <material>
            <script>
              <name>Gazebo/DarkGrey</name>
              <uri>file://media/materials/scripts/gazebo.material</uri>
            </script>
          </material>
        </visual>
        <gravity>1</gravity>
        <velocity_decay/>
        <self_collide>0</self_collide>
        <enable_wind>0</enable_wind>
        <kinematic>0</kinematic>
      </link>
      <joint name='LElbj' type='revolute'>
        <child>LElb</child>
        <parent>LShy</parent>
        <axis>
          <xyz>0 1 0</xyz>
          <limit>
            <lower>-2.3562</lower>
            <upper>0</upper>
            <effort>50</effort>
            <velocity>4</velocity>
          </limit>
          <dynamics>
            <damping>3</damping>
            <friction>0</friction>
            <spring_reference>0</spring_reference>
            <spring_stiffness>0</spring_stiffness>
          </dynamics>
          <use_parent_model_frame>1</use_parent_model_frame>
        </axis>
        <physics>
          <provide_feedback>1</provide_feedback>
          <ode>
            <provide_feedback>1</provide_feedback>
            <implicit_spring_damper>1</implicit_spring_damper>
            <cfm_damping>1</cfm_damping>
            <limit>
              <cfm>0</cfm>
              <erp>0.2</erp>
            </limit>
          </ode>
        </physics>
      </joint>
      <link name='LForearm'>
        <pose frame=''>0.005305 0.1558 0.036529 0 -0 0</pose>
        <inertial>
          <pose frame=''>0 0 -0.0282 0 -0 0</pose>
          <mass>0.933517</mass>
          <inertia>
            <ixx>0.001</ixx>
            <ixy>0</ixy>
            <ixz>0</ixz>
            <iyy>0.001</iyy>
            <iyz>0</iyz>
            <izz>0.001</izz>
          </inertia>
        </inertial>
        <collision name='LForearm_collision'>
          <pose frame=''>0 0 0.0718 3.14159 -0 -1.5708</pose>
          <geometry>
            <mesh>
              <scale>1 1 1</scale>
              <uri>model://coman_urdf/meshes/simple/Forearm0.STL</uri>
            </mesh>
          </geometry>
          <surface>
            <contact>
              <ode/>
            </contact>
            <friction>
              <ode/>
              <torsional>
                <ode/>
              </torsional>
            </friction>
            <bounce/>
          </surface>
          <max_contacts>10</max_contacts>
        </collision>
        <visual name='LForearm_visual'>
          <pose frame=''>0 0 0.0718 -3.14159 -0 1.5708</pose>
          <geometry>
            <mesh>
              <scale>0.1 0.1 0.1</scale>
              <uri>model://coman_urdf/meshes/Forearm0.STL</uri>
            </mesh>
          </geometry>
          <material>
            <script>
              <name>Gazebo/DarkGrey</name>
              <uri>file://media/materials/scripts/gazebo.material</uri>
            </script>
          </material>
        </visual>
        <gravity>1</gravity>
        <velocity_decay/>
        <self_collide>0</self_collide>
        <enable_wind>0</enable_wind>
        <kinematic>0</kinematic>
      </link>
      <joint name='LForearmPlate' type='revolute'>
        <child>LForearm</child>
        <parent>LElb</parent>
        <axis>
          <xyz>0 0 1</xyz>
          <limit>
            <lower>-1.5708</lower>
            <upper>1.5708</upper>
            <effort>5</effort>
            <velocity>4</velocity>
          </limit>
          <dynamics>
            <damping>0.03</damping>
            <friction>0</friction>
            <spring_reference>0</spring_reference>
            <spring_stiffness>0</spring_stiffness>
          </dynamics>
          <use_parent_model_frame>1</use_parent_model_frame>
        </axis>
        <physics>
          <provide_feedback>1</provide_feedback>
          <ode>
            <provide_feedback>1</provide_feedback>
            <implicit_spring_damper>1</implicit_spring_damper>
            <cfm_damping>1</cfm_damping>
            <limit>
              <cfm>0</cfm>
              <erp>0.2</erp>
            </limit>
          </ode>
        </physics>
        <sensor name='left_arm_ft' type='force_torque'>
          <force_torque>
            <frame>sensor</frame>
            <measure_direction>child_to_parent</measure_direction>
          </force_torque>
          <always_on>1</always_on>
          <visualize>1</visualize>
          <update_rate>1000</update_rate>
          <pose frame=''>0 0 0 0 -0 0</pose>
        </sensor>
      </joint>
      <link name='LWrMot2'>
        <pose frame=''>0.005305 0.1558 -0.050351 0 -0 0</pose>
        <inertial>
          <pose frame=''>0 0 0 0 -0 0</pose>
          <mass>0.260706</mass>
          <inertia>
            <ixx>0.000132</ixx>
            <ixy>0</ixy>
            <ixz>0</ixz>
            <iyy>0.000132</iyy>
            <iyz>0</iyz>
            <izz>5.213e-05</izz>
          </inertia>
        </inertial>
        <collision name='LWrMot2_collision'>
          <pose frame=''>0.025 0 0 3.14159 1.57079 -3e-06</pose>
          <geometry>
            <mesh>
              <scale>0.001 0.001 0.001</scale>
              <uri>model://coman_urdf/meshes/simple/Forearm1.STL</uri>
            </mesh>
          </geometry>
          <surface>
            <contact>
              <ode/>
            </contact>
            <friction>
              <ode/>
              <torsional>
                <ode/>
              </torsional>
            </friction>
            <bounce/>
          </surface>
          <max_contacts>10</max_contacts>
        </collision>
        <visual name='LWrMot2_visual'>
          <pose frame=''>0.025 0 0 3.14159 1.57079 -3e-06</pose>
          <geometry>
            <mesh>
              <scale>0.001 0.001 0.001</scale>
              <uri>model://coman_urdf/meshes/Forearm1.STL</uri>
            </mesh>
          </geometry>
          <material>
            <script>
              <name>Gazebo/Grey</name>
              <uri>file://media/materials/scripts/gazebo.material</uri>
            </script>
          </material>
        </visual>
        <gravity>1</gravity>
        <velocity_decay/>
        <self_collide>0</self_collide>
        <enable_wind>0</enable_wind>
        <kinematic>0</kinematic>
      </link>
      <joint name='LWrj1' type='revolute'>
        <child>LWrMot2</child>
        <parent>LForearm</parent>
        <axis>
          <xyz>0 1 0</xyz>
          <limit>
            <lower>-0.524</lower>
            <upper>0.524</upper>
            <effort>5</effort>
            <velocity>4</velocity>
          </limit>
          <dynamics>
            <damping>0.03</damping>
            <friction>0</friction>
            <spring_reference>0</spring_reference>
            <spring_stiffness>0</spring_stiffness>
          </dynamics>
          <use_parent_model_frame>1</use_parent_model_frame>
        </axis>
        <physics>
          <provide_feedback>1</provide_feedback>
          <ode>
            <provide_feedback>1</provide_feedback>
            <implicit_spring_damper>1</implicit_spring_damper>
            <cfm_damping>1</cfm_damping>
            <limit>
              <cfm>0</cfm>
              <erp>0.2</erp>
            </limit>
          </ode>
        </physics>
      </joint>
      <link name='LWrMot3'>
        <pose frame=''>0.005305 0.1558 -0.050351 0 -0 0</pose>
        <inertial>
          <pose frame=''>0 0 -0.059321 0 -0 0</pose>
          <mass>0.354008</mass>
          <inertia>
            <ixx>0.00124586</ixx>
            <ixy>0</ixy>
            <ixz>0</ixz>
            <iyy>0.00124586</iyy>
            <iyz>0</iyz>
            <izz>0.0010216</izz>
          </inertia>
        </inertial>
        <collision name='LWrMot3_collision'>
          <pose frame=''>0.025 -0.012 -0.02 3.14159 -0 -1.5708</pose>
          <geometry>
            <mesh>
              <scale>0.001 0.001 0.001</scale>
              <uri>model://coman_urdf/meshes/simple/Forearm2.STL</uri>
            </mesh>
          </geometry>
          <surface>
            <contact>
              <ode/>
            </contact>
            <friction>
              <ode/>
              <torsional>
                <ode/>
              </torsional>
            </friction>
            <bounce/>
          </surface>
          <max_contacts>10</max_contacts>
        </collision>
        <collision name='LWrMot3_fixed_joint_lump__LSoftHand_collision_1'>
          <pose frame=''>0.007 -0.01 -0.11 0 -0 0</pose>
          <geometry>
            <mesh>
              <scale>-0.001 0.001 0.001</scale>
              <uri>model://coman_urdf/meshes/simple/SoftHandOpen.STL</uri>
            </mesh>
          </geometry>
          <surface>
            <contact>
              <ode/>
            </contact>
            <friction>
              <ode/>
              <torsional>
                <ode/>
              </torsional>
            </friction>
            <bounce/>
          </surface>
          <max_contacts>10</max_contacts>
        </collision>
        <visual name='LWrMot3_visual'>
          <pose frame=''>0.025 -0.012 -0.02 3.14159 -0 -1.5708</pose>
          <geometry>
            <mesh>
              <scale>0.001 0.001 0.001</scale>
              <uri>model://coman_urdf/meshes/Forearm2.STL</uri>
            </mesh>
          </geometry>
          <material>
            <script>
              <name>Gazebo/Grey</name>
              <uri>file://media/materials/scripts/gazebo.material</uri>
            </script>
          </material>
        </visual>
        <visual name='LWrMot3_fixed_joint_lump__LSoftHand_visual_1'>
          <pose frame=''>0.007 -0.01 -0.11 -1.5708 0 0</pose>
          <geometry>
            <mesh>
              <scale>-0.1 0.1 0.1</scale>
              <uri>model://coman_urdf/meshes/SoftHandOpen.STL</uri>
            </mesh>
          </geometry>
          <material>
            <script>
              <name>Gazebo/DarkGrey</name>
              <uri>file://media/materials/scripts/gazebo.material</uri>
            </script>
          </material>
        </visual>
        <velocity_decay/>
        <gravity>1</gravity>
        <velocity_decay/>
        <self_collide>0</self_collide>
        <enable_wind>0</enable_wind>
        <kinematic>0</kinematic>
      </link>
      <joint name='LWrj2' type='revolute'>
        <child>LWrMot3</child>
        <parent>LWrMot2</parent>
        <axis>
          <xyz>1 0 0</xyz>
          <limit>
            <lower>-0.785375</lower>
            <upper>1.395</upper>
            <effort>5</effort>
            <velocity>4</velocity>
          </limit>
          <dynamics>
            <damping>0.03</damping>
            <friction>0</friction>
            <spring_reference>0</spring_reference>
            <spring_stiffness>0</spring_stiffness>
          </dynamics>
          <use_parent_model_frame>1</use_parent_model_frame>
        </axis>
        <physics>
          <provide_feedback>1</provide_feedback>
          <ode>
            <provide_feedback>1</provide_feedback>
            <implicit_spring_damper>1</implicit_spring_damper>
            <cfm_damping>1</cfm_damping>
            <limit>
              <cfm>0</cfm>
              <erp>0.2</erp>
            </limit>
          </ode>
        </physics>
      </joint>
      <link name='RShp'>
        <pose frame=''>0.005305 -0.0825 0.324329 0 -0 0</pose>
        <inertial>
          <pose frame=''>0.00995 -0.038682 0.000164 0 -0 0</pose>
          <mass>0.567822</mass>
          <inertia>
            <ixx>0.000783375</ixx>
            <ixy>0.000190358</ixy>
            <ixz>-3.00377e-06</ixz>
            <iyy>0.000633999</iyy>
            <iyz>4.38408e-06</iyz>
            <izz>0.00100805</izz>
          </inertia>
        </inertial>
        <collision name='RShp_collision'>
          <pose frame=''>-0.005305 0.0825 -0.844329 0 -0 -3.14159</pose>
          <geometry>
            <mesh>
              <scale>0.03937 0.03937 0.03937</scale>
              <uri>model://coman_urdf/meshes/simple/Arm0.STL</uri>
            </mesh>
          </geometry>
          <surface>
            <contact>
              <ode/>
            </contact>
            <friction>
              <ode/>
              <torsional>
                <ode/>
              </torsional>
            </friction>
            <bounce/>
          </surface>
          <max_contacts>10</max_contacts>
        </collision>
        <visual name='RShp_visual'>
          <pose frame=''>-0.005305 0.0825 -0.844329 0 -0 -3.14159</pose>
          <geometry>
            <mesh>
              <scale>0.03937 0.03937 0.03937</scale>
              <uri>model://coman_urdf/meshes/Arm0.STL</uri>
            </mesh>
          </geometry>
          <material>
            <script>
              <name>Gazebo/DarkGrey</name>
              <uri>file://media/materials/scripts/gazebo.material</uri>
            </script>
          </material>
        </visual>
        <gravity>1</gravity>
        <velocity_decay/>
        <self_collide>0</self_collide>
        <enable_wind>0</enable_wind>
        <kinematic>0</kinematic>
      </link>
      <joint name='RShSag' type='revolute'>
        <child>RShp</child>
        <parent>DWYTorso</parent>
        <axis>
          <xyz>0 1 0</xyz>
          <limit>
            <lower>-3.4034</lower>
            <upper>1.6581</upper>
            <effort>50</effort>
            <velocity>4</velocity>
          </limit>
          <dynamics>
            <damping>3</damping>
            <friction>0</friction>
            <spring_reference>0</spring_reference>
            <spring_stiffness>0</spring_stiffness>
          </dynamics>
          <use_parent_model_frame>1</use_parent_model_frame>
        </axis>
        <physics>
          <provide_feedback>1</provide_feedback>
          <ode>
            <provide_feedback>1</provide_feedback>
            <implicit_spring_damper>1</implicit_spring_damper>
            <cfm_damping>1</cfm_damping>
            <limit>
              <cfm>0</cfm>
              <erp>0.2</erp>
            </limit>
          </ode>
        </physics>
      </joint>
      <link name='RShr'>
        <pose frame=''>0.005305 -0.1558 0.324329 0 -0 0</pose>
        <inertial>
          <pose frame=''>-0.003894 2e-06 -0.004862 0 -0 0</pose>
          <mass>0.776838</mass>
          <inertia>
            <ixx>0.000458129</ixx>
            <ixy>-2.41111e-07</ixy>
            <ixz>9.25212e-06</ixz>
            <iyy>0.000430892</iyy>
            <iyz>-4.7217e-07</iyz>
            <izz>0.000341749</izz>
          </inertia>
        </inertial>
        <collision name='RShr_collision'>
          <pose frame=''>-0.005305 0.1558 -0.844329 0 -0 -3.14159</pose>
          <geometry>
            <mesh>
              <scale>0.03937 0.03937 0.03937</scale>
              <uri>model://coman_urdf/meshes/simple/Arm1.STL</uri>
            </mesh>
          </geometry>
          <surface>
            <contact>
              <ode/>
            </contact>
            <friction>
              <ode/>
              <torsional>
                <ode/>
              </torsional>
            </friction>
            <bounce/>
          </surface>
          <max_contacts>10</max_contacts>
        </collision>
        <visual name='RShr_visual'>
          <pose frame=''>-0.005305 0.1558 -0.844329 0 -0 -3.14159</pose>
          <geometry>
            <mesh>
              <scale>0.03937 0.03937 0.03937</scale>
              <uri>model://coman_urdf/meshes/Arm1.STL</uri>
            </mesh>
          </geometry>
          <material>
            <script>
              <name>Gazebo/DarkGrey</name>
              <uri>file://media/materials/scripts/gazebo.material</uri>
            </script>
          </material>
        </visual>
        <gravity>1</gravity>
        <velocity_decay/>
        <self_collide>0</self_collide>
        <enable_wind>0</enable_wind>
        <kinematic>0</kinematic>
      </link>
      <joint name='RShLat' type='revolute'>
        <child>RShr</child>
        <parent>RShp</parent>
        <axis>
          <xyz>1 0 0</xyz>
          <limit>
            <lower>-2.094</lower>
            <upper>0.31415</upper>
            <effort>50</effort>
            <velocity>4</velocity>
          </limit>
          <dynamics>
            <damping>3</damping>
            <friction>0</friction>
            <spring_reference>0</spring_reference>
            <spring_stiffness>0</spring_stiffness>
          </dynamics>
          <use_parent_model_frame>1</use_parent_model_frame>
        </axis>
        <physics>
          <provide_feedback>1</provide_feedback>
          <ode>
            <provide_feedback>1</provide_feedback>
            <implicit_spring_damper>1</implicit_spring_damper>
            <cfm_damping>1</cfm_damping>
            <limit>
              <cfm>0</cfm>
              <erp>0.2</erp>
            </limit>
          </ode>
        </physics>
      </joint>
      <link name='RShy'>
        <pose frame=''>0.005305 -0.1558 0.279521 0 -0 0</pose>
        <inertial>
          <pose frame=''>0.002271 -0.007109 -0.057455 0 -0 0</pose>
          <mass>1.04623</mass>
          <inertia>
            <ixx>0.00309346</ixx>
            <ixy>6.67028e-05</ixy>
            <ixz>0.000302223</ixz>
            <iyy>0.00291816</iyy>
            <iyz>-0.000526637</iyz>
            <izz>0.000808304</izz>
          </inertia>
        </inertial>
        <collision name='RShy_collision'>
          <pose frame=''>-0.005305 0.1558 -0.799521 0 -0 -3.14159</pose>
          <geometry>
            <mesh>
              <scale>0.03937 0.03937 0.03937</scale>
              <uri>model://coman_urdf/meshes/simple/Arm2.STL</uri>
            </mesh>
          </geometry>
          <surface>
            <contact>
              <ode/>
            </contact>
            <friction>
              <ode/>
              <torsional>
                <ode/>
              </torsional>
            </friction>
            <bounce/>
          </surface>
          <max_contacts>10</max_contacts>
        </collision>
        <visual name='RShy_visual'>
          <pose frame=''>-0.005305 0.1558 -0.799521 0 -0 -3.14159</pose>
          <geometry>
            <mesh>
              <scale>0.03937 0.03937 0.03937</scale>
              <uri>model://coman_urdf/meshes/Arm2.STL</uri>
            </mesh>
          </geometry>
          <material>
            <script>
              <name>Gazebo/DarkGrey</name>
              <uri>file://media/materials/scripts/gazebo.material</uri>
            </script>
          </material>
        </visual>
        <gravity>1</gravity>
        <velocity_decay/>
        <self_collide>0</self_collide>
        <enable_wind>0</enable_wind>
        <kinematic>0</kinematic>
      </link>
      <joint name='RShYaw' type='revolute'>
        <child>RShy</child>
        <parent>RShr</parent>
        <axis>
          <xyz>0 0 1</xyz>
          <limit>
            <lower>-1.5708</lower>
            <upper>1.5708</upper>
            <effort>50</effort>
            <velocity>4</velocity>
          </limit>
          <dynamics>
            <damping>3</damping>
            <friction>0</friction>
            <spring_reference>0</spring_reference>
            <spring_stiffness>0</spring_stiffness>
          </dynamics>
          <use_parent_model_frame>1</use_parent_model_frame>
        </axis>
        <physics>
          <provide_feedback>1</provide_feedback>
          <ode>
            <provide_feedback>1</provide_feedback>
            <implicit_spring_damper>1</implicit_spring_damper>
            <cfm_damping>1</cfm_damping>
            <limit>
              <cfm>0</cfm>
              <erp>0.2</erp>
            </limit>
          </ode>
        </physics>
      </joint>
      <link name='RElb'>
        <pose frame=''>0.020305 -0.1558 0.144329 0 -0 0</pose>
        <inertial>
          <pose frame=''>-0.000656 -0.000935 -0.000931 0 -0 0</pose>
          <mass>0.633069</mass>
          <inertia>
            <ixx>0.000225991</ixx>
            <ixy>-2.63765e-07</ixy>
            <ixz>-9.80073e-06</ixz>
            <iyy>0.000277813</iyy>
            <iyz>-2.04353e-06</iyz>
            <izz>0.00021879</izz>
          </inertia>
        </inertial>
        <collision name='RElb_collision'>
          <pose frame=''>0 0 0 3.14159 1.57079 -1.57079</pose>
          <geometry>
            <mesh>
              <scale>1 1 1</scale>
              <uri>model://coman_urdf/meshes/simple/Elbow.STL</uri>
            </mesh>
          </geometry>
          <surface>
            <contact>
              <ode/>
            </contact>
            <friction>
              <ode/>
              <torsional>
                <ode/>
              </torsional>
            </friction>
            <bounce/>
          </surface>
          <max_contacts>10</max_contacts>
        </collision>
        <visual name='RElb_visual'>
          <pose frame=''>0 0 0 3.14159 1.57079 -1.57079</pose>
          <geometry>
            <mesh>
              <scale>1 1 1</scale>
              <uri>model://coman_urdf/meshes/Elbow.STL</uri>
            </mesh>
          </geometry>
          <material>
            <script>
              <name>Gazebo/DarkGrey</name>
              <uri>file://media/materials/scripts/gazebo.material</uri>
            </script>
          </material>
        </visual>
        <gravity>1</gravity>
        <velocity_decay/>
        <self_collide>0</self_collide>
        <enable_wind>0</enable_wind>
        <kinematic>0</kinematic>
      </link>
      <joint name='RElbj' type='revolute'>
        <child>RElb</child>
        <parent>RShy</parent>
        <axis>
          <xyz>0 1 0</xyz>
          <limit>
            <lower>-2.3562</lower>
            <upper>0</upper>
            <effort>50</effort>
            <velocity>4</velocity>
          </limit>
          <dynamics>
            <damping>3</damping>
            <friction>0</friction>
            <spring_reference>0</spring_reference>
            <spring_stiffness>0</spring_stiffness>
          </dynamics>
          <use_parent_model_frame>1</use_parent_model_frame>
        </axis>
        <physics>
          <provide_feedback>1</provide_feedback>
          <ode>
            <provide_feedback>1</provide_feedback>
            <implicit_spring_damper>1</implicit_spring_damper>
            <cfm_damping>1</cfm_damping>
            <limit>
              <cfm>0</cfm>
              <erp>0.2</erp>
            </limit>
          </ode>
        </physics>
      </joint>
      <link name='RForearm'>
        <pose frame=''>0.005305 -0.1558 0.036529 0 -0 0</pose>
        <inertial>
          <pose frame=''>0 0 -0.0282 0 -0 0</pose>
          <mass>0.933517</mass>
          <inertia>
            <ixx>0.001</ixx>
            <ixy>0</ixy>
            <ixz>0</ixz>
            <iyy>0.001</iyy>
            <iyz>0</iyz>
            <izz>0.001</izz>
          </inertia>
        </inertial>
        <collision name='RForearm_collision'>
          <pose frame=''>0 0 0.0718 3.14159 -0 -1.5708</pose>
          <geometry>
            <mesh>
              <scale>1 1 1</scale>
              <uri>model://coman_urdf/meshes/simple/Forearm0.STL</uri>
            </mesh>
          </geometry>
          <surface>
            <contact>
              <ode/>
            </contact>
            <friction>
              <ode/>
              <torsional>
                <ode/>
              </torsional>
            </friction>
            <bounce/>
          </surface>
          <max_contacts>10</max_contacts>
        </collision>
        <visual name='RForearm_visual'>
          <pose frame=''>0 0 0.0718 -3.14159 -0 1.5708</pose>
          <geometry>
            <mesh>
              <scale>0.1 0.1 0.1</scale>
              <uri>model://coman_urdf/meshes/Forearm0.STL</uri>
            </mesh>
          </geometry>
          <material>
            <script>
              <name>Gazebo/DarkGrey</name>
              <uri>file://media/materials/scripts/gazebo.material</uri>
            </script>
          </material>
        </visual>
        <gravity>1</gravity>
        <velocity_decay/>
        <self_collide>0</self_collide>
        <enable_wind>0</enable_wind>
        <kinematic>0</kinematic>
      </link>
      <joint name='RForearmPlate' type='revolute'>
        <child>RForearm</child>
        <parent>RElb</parent>
        <axis>
          <xyz>0 0 1</xyz>
          <limit>
            <lower>-1.5708</lower>
            <upper>1.5708</upper>
            <effort>5</effort>
            <velocity>4</velocity>
          </limit>
          <dynamics>
            <damping>0.03</damping>
            <friction>0</friction>
            <spring_reference>0</spring_reference>
            <spring_stiffness>0</spring_stiffness>
          </dynamics>
          <use_parent_model_frame>1</use_parent_model_frame>
        </axis>
        <physics>
          <provide_feedback>1</provide_feedback>
          <ode>
            <provide_feedback>1</provide_feedback>
            <implicit_spring_damper>1</implicit_spring_damper>
            <cfm_damping>1</cfm_damping>
            <limit>
              <cfm>0</cfm>
              <erp>0.2</erp>
            </limit>
          </ode>
        </physics>
        <sensor name='right_arm_ft' type='force_torque'>
          <force_torque>
            <frame>sensor</frame>
            <measure_direction>child_to_parent</measure_direction>
          </force_torque>
          <always_on>1</always_on>
          <visualize>1</visualize>
          <update_rate>1000</update_rate>
          <pose frame=''>0 0 0 0 -0 0</pose>
        </sensor>
      </joint>
      <link name='RWrMot2'>
        <pose frame=''>0.005305 -0.1558 -0.050351 0 -0 0</pose>
        <inertial>
          <pose frame=''>0 0 0 0 -0 0</pose>
          <mass>0.260706</mass>
          <inertia>
            <ixx>0.000132</ixx>
            <ixy>0</ixy>
            <ixz>0</ixz>
            <iyy>0.000132</iyy>
            <iyz>0</iyz>
            <izz>5.213e-05</izz>
          </inertia>
        </inertial>
        <collision name='RWrMot2_collision'>
          <pose frame=''>0.025 0 0 3.14159 1.57079 -3e-06</pose>
          <geometry>
            <mesh>
              <scale>0.001 0.001 0.001</scale>
              <uri>model://coman_urdf/meshes/simple/Forearm1.STL</uri>
            </mesh>
          </geometry>
          <surface>
            <contact>
              <ode/>
            </contact>
            <friction>
              <ode/>
              <torsional>
                <ode/>
              </torsional>
            </friction>
            <bounce/>
          </surface>
          <max_contacts>10</max_contacts>
        </collision>
        <visual name='RWrMot2_visual'>
          <pose frame=''>0.025 0 0 3.14159 1.57079 -3e-06</pose>
          <geometry>
            <mesh>
              <scale>0.001 0.001 0.001</scale>
              <uri>model://coman_urdf/meshes/Forearm1.STL</uri>
            </mesh>
          </geometry>
          <material>
            <script>
              <name>Gazebo/Grey</name>
              <uri>file://media/materials/scripts/gazebo.material</uri>
            </script>
          </material>
        </visual>
        <gravity>1</gravity>
        <velocity_decay/>
        <self_collide>0</self_collide>
        <enable_wind>0</enable_wind>
        <kinematic>0</kinematic>
      </link>
      <joint name='RWrj1' type='revolute'>
        <child>RWrMot2</child>
        <parent>RForearm</parent>
        <axis>
          <xyz>0 1 0</xyz>
          <limit>
            <lower>-0.524</lower>
            <upper>0.524</upper>
            <effort>5</effort>
            <velocity>4</velocity>
          </limit>
          <dynamics>
            <damping>0.03</damping>
            <friction>0</friction>
            <spring_reference>0</spring_reference>
            <spring_stiffness>0</spring_stiffness>
          </dynamics>
          <use_parent_model_frame>1</use_parent_model_frame>
        </axis>
        <physics>
          <provide_feedback>1</provide_feedback>
          <ode>
            <provide_feedback>1</provide_feedback>
            <implicit_spring_damper>1</implicit_spring_damper>
            <cfm_damping>1</cfm_damping>
            <limit>
              <cfm>0</cfm>
              <erp>0.2</erp>
            </limit>
          </ode>
        </physics>
      </joint>
      <link name='RWrMot3'>
        <pose frame=''>0.005305 -0.1558 -0.050351 0 -0 0</pose>
        <inertial>
          <pose frame=''>0 0 -0.059321 0 -0 0</pose>
          <mass>0.354008</mass>
          <inertia>
            <ixx>0.00124586</ixx>
            <ixy>0</ixy>
            <ixz>0</ixz>
            <iyy>0.00124586</iyy>
            <iyz>0</iyz>
            <izz>0.0010216</izz>
          </inertia>
        </inertial>
        <collision name='RWrMot3_collision'>
          <pose frame=''>0.025 -0.012 -0.02 3.14159 -0 -1.5708</pose>
          <geometry>
            <mesh>
              <scale>0.001 0.001 0.001</scale>
              <uri>model://coman_urdf/meshes/simple/Forearm2.STL</uri>
            </mesh>
          </geometry>
          <surface>
            <contact>
              <ode/>
            </contact>
            <friction>
              <ode/>
              <torsional>
                <ode/>
              </torsional>
            </friction>
            <bounce/>
          </surface>
          <max_contacts>10</max_contacts>
        </collision>
        <collision name='RWrMot3_fixed_joint_lump__RSoftHand_collision_1'>
          <pose frame=''>0 0.01 -0.11 0 -0 -3.14159</pose>
          <geometry>
            <mesh>
              <scale>0.001 0.001 0.001</scale>
              <uri>model://coman_urdf/meshes/simple/SoftHandOpen.STL</uri>
            </mesh>
          </geometry>
          <surface>
            <contact>
              <ode/>
            </contact>
            <friction>
              <ode/>
              <torsional>
                <ode/>
              </torsional>
            </friction>
            <bounce/>
          </surface>
          <max_contacts>10</max_contacts>
        </collision>
        <visual name='RWrMot3_visual'>
          <pose frame=''>0.025 -0.012 -0.02 3.14159 -0 -1.5708</pose>
          <geometry>
            <mesh>
              <scale>0.001 0.001 0.001</scale>
              <uri>model://coman_urdf/meshes/Forearm2.STL</uri>
            </mesh>
          </geometry>
          <material>
            <script>
              <name>Gazebo/Grey</name>
              <uri>file://media/materials/scripts/gazebo.material</uri>
            </script>
          </material>
        </visual>
        <visual name='RWrMot3_fixed_joint_lump__RSoftHand_visual_1'>
          <pose frame=''>0.007 0.01 -0.11 -1.5708 -0 -3.14159</pose>
          <geometry>
            <mesh>
              <scale>0.1 0.1 0.1</scale>
              <uri>model://coman_urdf/meshes/SoftHandOpen.STL</uri>
            </mesh>
          </geometry>
          <material>
            <script>
              <name>Gazebo/DarkGrey</name>
              <uri>file://media/materials/scripts/gazebo.material</uri>
            </script>
          </material>
        </visual>
        <velocity_decay/>
        <gravity>1</gravity>
        <velocity_decay/>
        <self_collide>0</self_collide>
        <enable_wind>0</enable_wind>
        <kinematic>0</kinematic>
      </link>
      <joint name='RWrj2' type='revolute'>
        <child>RWrMot3</child>
        <parent>RWrMot2</parent>
        <axis>
          <xyz>1 0 0</xyz>
          <limit>
            <lower>-1.395</lower>
            <upper>0.785375</upper>
            <effort>5</effort>
            <velocity>4</velocity>
          </limit>
          <dynamics>
            <damping>0.03</damping>
            <friction>0</friction>
            <spring_reference>0</spring_reference>
            <spring_stiffness>0</spring_stiffness>
          </dynamics>
          <use_parent_model_frame>1</use_parent_model_frame>
        </axis>
        <physics>
          <provide_feedback>1</provide_feedback>
          <ode>
            <provide_feedback>1</provide_feedback>
            <implicit_spring_damper>1</implicit_spring_damper>
            <cfm_damping>1</cfm_damping>
            <limit>
              <cfm>0</cfm>
              <erp>0.2</erp>
            </limit>
          </ode>
        </physics>
      </joint>
      <static>0</static>
      <plugin name='xbot_plugin_handler' filename='libGazeboXBotPlugin.so'/>
      <pose frame=''>2.05 1 0.5 0 0 -0.35</pose>
    </model>
    <audio>
      <device>default</device>
    </audio>
    <model name='euro_pallet'>
      <link name='link'>
        <pose frame=''>0 0 0 0 -0 0</pose>
        <inertial>
          <mass>20</mass>
          <inertia>
            <ixx>2.43</ixx>
            <ixy>0</ixy>
            <ixz>0</ixz>
            <iyy>1.1</iyy>
            <iyz>0</iyz>
            <izz>3.47</izz>
          </inertia>
        </inertial>
        <collision name='collision'>
          <pose frame=''>0 0 0.05 0 -0 0</pose>
          <geometry>
            <mesh>
              <uri>model://euro_pallet/meshes/pallet.dae</uri>
              <scale>0.1 0.1 0.1</scale>
            </mesh>
          </geometry>
          <max_contacts>10</max_contacts>
          <surface>
            <contact>
              <ode/>
            </contact>
            <bounce/>
            <friction>
              <torsional>
                <ode/>
              </torsional>
              <ode/>
            </friction>
          </surface>
        </collision>
        <visual name='visual'>
          <pose frame=''>0 0 0.05 0 -0 0</pose>
          <geometry>
            <mesh>
              <uri>model://euro_pallet/meshes/pallet.dae</uri>
              <scale>0.1 0.1 0.1</scale>
            </mesh>
          </geometry>
        </visual>
        <self_collide>0</self_collide>
        <enable_wind>0</enable_wind>
        <kinematic>0</kinematic>
      </link>
      <pose frame=''>4.1926 0.254141 0 0 -0 0</pose>
    </model>
    <model name='cardboard_box'>
      <pose frame=''>4.19944 0.527112 0.15 0 -0 0</pose>
      <link name='link'>
        <inertial>
          <mass>2</mass>
          <inertia>
            <ixx>0.0416667</ixx>
            <ixy>0</ixy>
            <ixz>0</ixz>
            <iyy>0.0566667</iyy>
            <iyz>0</iyz>
            <izz>0.0683333</izz>
          </inertia>
        </inertial>
        <collision name='collision'>
          <geometry>
            <box>
              <size>0.5 0.4 0.3</size>
            </box>
          </geometry>
          <surface>
            <friction>
              <ode>
                <mu>1</mu>
                <mu2>1</mu2>
              </ode>
              <torsional>
                <ode/>
              </torsional>
            </friction>
            <contact>
              <ode>
                <kp>1e+07</kp>
                <kd>1</kd>
                <min_depth>0.001</min_depth>
                <max_vel>0.1</max_vel>
              </ode>
            </contact>
            <bounce/>
          </surface>
          <max_contacts>10</max_contacts>
        </collision>
        <visual name='visual'>
          <pose frame=''>0 0 -0.15 0 -0 0</pose>
          <geometry>
            <mesh>
              <uri>model://cardboard_box/meshes/cardboard_box.dae</uri>
              <scale>1.25932 1.00745 0.755591</scale>
            </mesh>
          </geometry>
        </visual>
        <self_collide>0</self_collide>
        <enable_wind>0</enable_wind>
        <kinematic>0</kinematic>
      </link>
    </model>
    <model name='cardboard_box_0'>
      <pose frame=''>4.22615 1.17172 0.15 0 -0 0</pose>
      <link name='link'>
        <inertial>
          <mass>2</mass>
          <inertia>
            <ixx>0.0416667</ixx>
            <ixy>0</ixy>
            <ixz>0</ixz>
            <iyy>0.0566667</iyy>
            <iyz>0</iyz>
            <izz>0.0683333</izz>
          </inertia>
        </inertial>
        <collision name='collision'>
          <geometry>
            <box>
              <size>0.5 0.4 0.3</size>
            </box>
          </geometry>
          <surface>
            <friction>
              <ode>
                <mu>1</mu>
                <mu2>1</mu2>
              </ode>
              <torsional>
                <ode/>
              </torsional>
            </friction>
            <contact>
              <ode>
                <kp>1e+07</kp>
                <kd>1</kd>
                <min_depth>0.001</min_depth>
                <max_vel>0.1</max_vel>
              </ode>
            </contact>
            <bounce/>
          </surface>
          <max_contacts>10</max_contacts>
        </collision>
        <visual name='visual'>
          <pose frame=''>0 0 -0.15 0 -0 0</pose>
          <geometry>
            <mesh>
              <uri>model://cardboard_box/meshes/cardboard_box.dae</uri>
              <scale>1.25932 1.00745 0.755591</scale>
            </mesh>
          </geometry>
        </visual>
        <self_collide>0</self_collide>
        <enable_wind>0</enable_wind>
        <kinematic>0</kinematic>
      </link>
    </model>
    <model name='cardboard_box_1'>
      <pose frame=''>4.1864 0.019936 0.15 0 -0 0</pose>
      <link name='link'>
        <inertial>
          <mass>2</mass>
          <inertia>
            <ixx>0.0416667</ixx>
            <ixy>0</ixy>
            <ixz>0</ixz>
            <iyy>0.0566667</iyy>
            <iyz>0</iyz>
            <izz>0.0683333</izz>
          </inertia>
        </inertial>
        <collision name='collision'>
          <geometry>
            <box>
              <size>0.5 0.4 0.3</size>
            </box>
          </geometry>
          <surface>
            <friction>
              <ode>
                <mu>1</mu>
                <mu2>1</mu2>
              </ode>
              <torsional>
                <ode/>
              </torsional>
            </friction>
            <contact>
              <ode>
                <kp>1e+07</kp>
                <kd>1</kd>
                <min_depth>0.001</min_depth>
                <max_vel>0.1</max_vel>
              </ode>
            </contact>
            <bounce/>
          </surface>
          <max_contacts>10</max_contacts>
        </collision>
        <visual name='visual'>
          <pose frame=''>0 0 -0.15 0 -0 0</pose>
          <geometry>
            <mesh>
              <uri>model://cardboard_box/meshes/cardboard_box.dae</uri>
              <scale>1.25932 1.00745 0.755591</scale>
            </mesh>
          </geometry>
        </visual>
        <self_collide>0</self_collide>
        <enable_wind>0</enable_wind>
        <kinematic>0</kinematic>
      </link>
    </model>
    <model name='cardboard_box_2'>
      <pose frame=''>4.05205 0.493213 0.15 0 -0 0</pose>
      <link name='link'>
        <inertial>
          <mass>2</mass>
          <inertia>
            <ixx>0.0416667</ixx>
            <ixy>0</ixy>
            <ixz>0</ixz>
            <iyy>0.0566667</iyy>
            <iyz>0</iyz>
            <izz>0.0683333</izz>
          </inertia>
        </inertial>
        <collision name='collision'>
          <geometry>
            <box>
              <size>0.5 0.4 0.3</size>
            </box>
          </geometry>
          <surface>
            <friction>
              <ode>
                <mu>1</mu>
                <mu2>1</mu2>
              </ode>
              <torsional>
                <ode/>
              </torsional>
            </friction>
            <contact>
              <ode>
                <kp>1e+07</kp>
                <kd>1</kd>
                <min_depth>0.001</min_depth>
                <max_vel>0.1</max_vel>
              </ode>
            </contact>
            <bounce/>
          </surface>
          <max_contacts>10</max_contacts>
        </collision>
        <visual name='visual'>
          <pose frame=''>0 0 -0.15 0 -0 0</pose>
          <geometry>
            <mesh>
              <uri>model://cardboard_box/meshes/cardboard_box.dae</uri>
              <scale>1.25932 1.00745 0.755591</scale>
            </mesh>
          </geometry>
        </visual>
        <self_collide>0</self_collide>
        <enable_wind>0</enable_wind>
        <kinematic>0</kinematic>
      </link>
    </model>
    <model name='cardboard_box_3'>
      <pose frame=''>3.9383 0.028768 0.15 0 -0 0</pose>
      <link name='link'>
        <inertial>
          <mass>2</mass>
          <inertia>
            <ixx>0.0416667</ixx>
            <ixy>0</ixy>
            <ixz>0</ixz>
            <iyy>0.0566667</iyy>
            <iyz>0</iyz>
            <izz>0.0683333</izz>
          </inertia>
        </inertial>
        <collision name='collision'>
          <geometry>
            <box>
              <size>0.5 0.4 0.3</size>
            </box>
          </geometry>
          <surface>
            <friction>
              <ode>
                <mu>1</mu>
                <mu2>1</mu2>
              </ode>
              <torsional>
                <ode/>
              </torsional>
            </friction>
            <contact>
              <ode>
                <kp>1e+07</kp>
                <kd>1</kd>
                <min_depth>0.001</min_depth>
                <max_vel>0.1</max_vel>
              </ode>
            </contact>
            <bounce/>
          </surface>
          <max_contacts>10</max_contacts>
        </collision>
        <visual name='visual'>
          <pose frame=''>0 0 -0.15 0 -0 0</pose>
          <geometry>
            <mesh>
              <uri>model://cardboard_box/meshes/cardboard_box.dae</uri>
              <scale>1.25932 1.00745 0.755591</scale>
            </mesh>
          </geometry>
        </visual>
        <self_collide>0</self_collide>
        <enable_wind>0</enable_wind>
        <kinematic>0</kinematic>
      </link>
    </model>
    <model name='cardboard_box_4'>
      <pose frame=''>4.07335 0.276164 0.15 0 -0 -0.35</pose>
      <link name='link'>
        <inertial>
          <mass>2</mass>
          <inertia>
            <ixx>0.0416667</ixx>
            <ixy>0</ixy>
            <ixz>0</ixz>
            <iyy>0.0566667</iyy>
            <iyz>0</iyz>
            <izz>0.0683333</izz>
          </inertia>
        </inertial>
        <collision name='collision'>
          <geometry>
            <box>
              <size>0.5 0.4 0.3</size>
            </box>
          </geometry>
          <surface>
            <friction>
              <ode>
                <mu>1</mu>
                <mu2>1</mu2>
              </ode>
              <torsional>
                <ode/>
              </torsional>
            </friction>
            <contact>
              <ode>
                <kp>1e+07</kp>
                <kd>1</kd>
                <min_depth>0.001</min_depth>
                <max_vel>0.1</max_vel>
              </ode>
            </contact>
            <bounce/>
          </surface>
          <max_contacts>10</max_contacts>
        </collision>
        <visual name='visual'>
          <pose frame=''>0 0 -0.15 0 -0 0</pose>
          <geometry>
            <mesh>
              <uri>model://cardboard_box_modified/meshes/cardboard_box.dae</uri>
              <scale>1 1 1</scale>
            </mesh>
          </geometry>
        </visual>
        <self_collide>0</self_collide>
        <enable_wind>0</enable_wind>
        <kinematic>0</kinematic>
      </link>
    </model>
    <model name='euro_pallet_0'>
      <link name='link'>
        <pose frame=''>0 0 0 0 -0 0</pose>
        <inertial>
          <mass>20</mass>
          <inertia>
            <ixx>2.43</ixx>
            <ixy>0</ixy>
            <ixz>0</ixz>
            <iyy>1.1</iyy>
            <iyz>0</iyz>
            <izz>3.47</izz>
          </inertia>
        </inertial>
        <collision name='collision'>
          <pose frame=''>0 0 0.05 0 -0 0</pose>
          <geometry>
            <mesh>
              <uri>model://euro_pallet/meshes/pallet.dae</uri>
              <scale>0.1 0.1 0.1</scale>
            </mesh>
          </geometry>
          <max_contacts>10</max_contacts>
          <surface>
            <contact>
              <ode/>
            </contact>
            <bounce/>
            <friction>
              <torsional>
                <ode/>
              </torsional>
              <ode/>
            </friction>
          </surface>
        </collision>
        <visual name='visual'>
          <pose frame=''>0 0 0.05 0 -0 0</pose>
          <geometry>
            <mesh>
              <uri>model://euro_pallet/meshes/pallet.dae</uri>
              <scale>0.1 0.1 0.1</scale>
            </mesh>
          </geometry>
        </visual>
        <self_collide>0</self_collide>
        <enable_wind>0</enable_wind>
        <kinematic>0</kinematic>
      </link>
      <pose frame=''>4.14844 -0.584794 0 0 -0 0</pose>
    </model>
    <light name='user_point_light_0' type='point'>
      <pose frame=''>3.20899 1.15864 1 0 -0 0</pose>
      <diffuse>0.5 0.5 0.5 1</diffuse>
      <specular>0.1 0.1 0.1 1</specular>
      <attenuation>
        <range>20</range>
        <constant>0.5</constant>
        <linear>0.01</linear>
        <quadratic>0.001</quadratic>
      </attenuation>
      <cast_shadows>0</cast_shadows>
      <direction>0 0 -1</direction>
    </light>
    <state world_name='default'>
      <sim_time>475 556000000</sim_time>
      <real_time>38 2561356</real_time>
      <wall_time>1615485179 210828766</wall_time>
      <iterations>29175</iterations>
      <model name='cardboard_box'>
        <pose frame=''>4.16003 0.519714 0.293995 0 -1e-06 0.000255</pose>
        <scale>1 1 1</scale>
        <link name='link'>
          <pose frame=''>4.16003 0.519714 0.293995 0 -1e-06 0.000255</pose>
          <velocity>0 0 0 0 -0 0</velocity>
          <acceleration>4.22945 -0.397237 -9.75115 -0.732813 0.020546 2.92581</acceleration>
          <wrench>8.45889 -0.794475 -19.5023 0 -0 0</wrench>
        </link>
      </model>
      <model name='cardboard_box_0'>
        <pose frame=''>4.16808 1.20767 0.149 0 -0 0.585785</pose>
        <scale>1 1 1</scale>
        <link name='link'>
          <pose frame=''>4.16808 1.20767 0.149 0 -0 0.585785</pose>
          <velocity>0 0 0 0 -0 0</velocity>
          <acceleration>-8e-06 1.1e-05 -0 -7.5e-05 -6.7e-05 0</acceleration>
          <wrench>-1.6e-05 2.2e-05 -1e-06 0 -0 0</wrench>
        </link>
      </model>
      <model name='cardboard_box_1'>
        <pose frame=''>4.17637 0.019744 0.29539 -0.006993 5e-06 0.017585</pose>
        <scale>1 1 1</scale>
        <link name='link'>
          <pose frame=''>4.17637 0.019744 0.29539 -0.006993 5e-06 0.017585</pose>
          <velocity>0 0 0 0 -0 0</velocity>
          <acceleration>2.95717 0.998677 -4.70176 2.34742 1.15449 2.40677</acceleration>
          <wrench>5.91434 1.99735 -9.40352 0 -0 0</wrench>
        </link>
      </model>
      <model name='cardboard_box_2'>
        <pose frame=''>4.20241 0.49666 0.592994 -0 -3e-06 3.10032</pose>
        <scale>1 1 1</scale>
        <link name='link'>
          <pose frame=''>4.20241 0.49666 0.592994 -0 -3e-06 3.10032</pose>
          <velocity>0 0 0 0 -0 0</velocity>
          <acceleration>2.95168 -0.336298 -5.74778 2.76308 1.14386 -0.355869</acceleration>
          <wrench>5.90336 -0.672596 -11.4956 0 -0 0</wrench>
        </link>
      </model>
      <model name='cardboard_box_3'>
        <pose frame=''>4.16637 0.029203 0.594329 -0.006992 -0.00029 -0.024714</pose>
        <scale>1 1 1</scale>
        <link name='link'>
          <pose frame=''>4.16637 0.029203 0.594329 -0.006992 -0.00029 -0.024714</pose>
          <velocity>0 0 0 0 -0 0</velocity>
          <acceleration>2.9336 2.60485 -1.65571 -0.315441 -0.914883 2.1188</acceleration>
          <wrench>5.8672 5.20969 -3.31142 0 -0 0</wrench>
        </link>
      </model>
      <model name='cardboard_box_4'>
        <pose frame=''>4.20182 0.293438 0.892828 -0.002964 -0.000964 -0.362961</pose>
        <scale>1 1 1</scale>
        <link name='link'>
          <pose frame=''>4.20182 0.293438 0.892828 -0.002964 -0.000964 -0.362961</pose>
          <velocity>0 0 0 0 -0 0</velocity>
          <acceleration>0.90033 1.83701 -3.30045 1.26787 0.028728 -2.54637</acceleration>
          <wrench>1.80066 3.67402 -6.6009 0 -0 0</wrench>
        </link>
      </model>
      <model name='coman'>
        <pose frame=''>0.728559 0.250016 0.516744 1.7e-05 -0.00013 -0.393873</pose>
        <scale>1 1 1</scale>
        <link name='DWL'>
          <pose frame=''>0.747272 0.242239 0.635867 1.8e-05 -8.5e-05 -0.393871</pose>
          <velocity>-3.4e-05 0.000101 0.000122 -0.000999 -0.002835 0.004335</velocity>
          <acceleration>-0.11433 0.03684 0.033957 -1.79139 -1.2255 -0.301843</acceleration>
          <wrench>-0.062411 0.02011 0.018537 0 -0 0</wrench>
        </link>
        <link name='DWS'>
          <pose frame=''>0.747271 0.24224 0.635859 -4.3e-05 -0.003127 -0.393864</pose>
          <velocity>-3.9e-05 9.5e-05 0.000102 4.5e-05 0.000463 0.004338</velocity>
          <acceleration>-0.081767 0.001665 0.022595 2.42334 0.958499 -0.503059</acceleration>
          <wrench>-0.061651 0.001255 0.017036 0 -0 0</wrench>
        </link>
        <link name='DWYTorso'>
          <pose frame=''>0.747134 0.2423 0.683352 2.8e-05 -0.003114 -0.393868</pose>
          <velocity>-2.5e-05 7.1e-05 8.3e-05 0.000524 0.000276 -0.000415</velocity>
          <acceleration>-0.009758 0.042728 0.030476 0.29109 0.010424 0.354624</acceleration>
          <wrench>-0.067835 0.297034 0.211863 0 -0 0</wrench>
        </link>
        <link name='LElb'>
          <pose frame=''>0.806981 0.386122 0.661052 -9e-05 -0.003212 -0.393872</pose>
          <velocity>2.3e-05 1.7e-05 0.000112 7.8e-05 -0 0.002392</velocity>
          <acceleration>0.047629 0.059091 0.072099 2.12025 1.0284 -2.13465</acceleration>
          <wrench>0.030152 0.037408 0.045644 0 -0 0</wrench>
        </link>
        <link name='LFoot'>
          <pose frame=''>0.756464 0.317087 0.089958 1e-06 -0.000115 -0.393695</pose>
          <velocity>2.3e-05 7e-05 8e-05 -0.000742 0.00024 1.2e-05</velocity>
          <acceleration>0.038364 0.077294 0.034923 -1.75558 -0.19808 -0.836643</acceleration>
          <wrench>0.025568 0.051514 0.023275 0 -0 0</wrench>
        </link>
        <link name='LFootmot'>
          <pose frame=''>0.756464 0.317087 0.089957 2.1e-05 -5.6e-05 -0.393696</pose>
          <velocity>3.1e-05 8.7e-05 7.4e-05 -0.000182 0.000404 0.000167</velocity>
          <acceleration>0.074356 0.148386 0.052197 0.399913 -0.202959 -2.33107</acceleration>
          <wrench>0.054274 0.10831 0.0381 0 -0 0</wrench>
        </link>
        <link name='LForearm'>
          <pose frame=''>0.793443 0.391737 0.553204 -9.1e-05 -0.003213 -0.393874</pose>
          <velocity>-1e-06 -1.6e-05 0.000113 7.4e-05 -0 -0.002</velocity>
          <acceleration>-0.011286 -0.028741 0.075214 -0.016828 0.254719 2.34678</acceleration>
          <wrench>-0.010536 -0.02683 0.070213 0 -0 0</wrench>
        </link>
        <link name='LHipMot'>
          <pose frame=''>0.737383 0.271254 0.516749 0.000104 -9.1e-05 -0.393872</pose>
          <velocity>0.000186 -8.4e-05 7e-05 -0.000158 -0.000263 0.004402</velocity>
          <acceleration>0.081092 -0.012795 0.036073 -2.16914 0.184027 2.01538</acceleration>
          <wrench>0.072381 -0.011421 0.032198 0 -0 0</wrench>
        </link>
        <link name='LLowLeg'>
          <pose frame=''>0.756446 0.317073 0.290955 9.8e-05 -5.7e-05 -0.393708</pose>
          <velocity>9.4e-05 6.8e-05 7e-05 9.6e-05 0.000305 0.000387</velocity>
          <acceleration>0.061511 0.122572 0.056374 0.525439 0.388018 -3.08836</acceleration>
          <wrench>0.086719 0.172805 0.079477 0 -0 0</wrench>
        </link>
        <link name='LShp'>
          <pose frame=''>0.764509 0.324415 0.841009 -2.7e-05 -0.003003 -0.39387</pose>
          <velocity>5.3e-05 -2e-05 0.000103 0.000353 0.000253 -0.000426</velocity>
          <acceleration>0.017603 0.025768 0.062269 0.508381 -1.33184 -2.81817</acceleration>
          <wrench>0.009996 0.014631 0.035358 0 -0 0</wrench>
        </link>
        <link name='LShr'>
          <pose frame=''>0.792639 0.392102 0.841007 -0.000104 -0.002983 -0.393871</pose>
          <velocity>8.1e-05 -3.2e-05 0.000121 0.0001 0.00042 -0.000441</velocity>
          <acceleration>0.026696 0.024509 0.069185 2.91944 0.804374 -2.79435</acceleration>
          <wrench>0.020739 0.019039 0.053746 0 -0 0</wrench>
        </link>
        <link name='LShy'>
          <pose frame=''>0.792762 0.392046 0.796199 -0.0001 -0.002983 -0.393871</pose>
          <velocity>6.5e-05 -3e-05 0.00012 0.000104 0.000416 0.002394</velocity>
          <acceleration>-0.007368 0.027748 0.06852 -1.16572 0.830776 -1.72388</acceleration>
          <wrench>-0.007709 0.02903 0.071688 0 -0 0</wrench>
        </link>
        <link name='LThighLowLeg'>
          <pose frame=''>0.756432 0.317065 0.414355 0.000102 -8.1e-05 -0.393711</pose>
          <velocity>5e-05 6.8e-05 6.8e-05 -5.2e-05 -0.00034 0.000433</velocity>
          <acceleration>0.049089 0.09532 0.055915 1.10264 0.267692 -0.431267</acceleration>
          <wrench>0.083457 0.162054 0.095061 0 -0 0</wrench>
        </link>
        <link name='LThighUpLeg'>
          <pose frame=''>0.756419 0.317056 0.516755 0.000103 -8.2e-05 -0.393868</pose>
          <velocity>-4e-06 2.6e-05 8.4e-05 4e-06 -0.00034 0.004335</velocity>
          <acceleration>0.001836 0.064918 0.070068 1.48686 0.514627 -0.79787</acceleration>
          <wrench>0.001881 0.066515 0.071792 0 -0 0</wrench>
        </link>
        <link name='LWrMot2'>
          <pose frame=''>0.793698 0.391623 0.466325 -9.1e-05 -0.003213 -0.393874</pose>
          <velocity>-1e-06 -1e-05 0.000112 5.2e-05 -5.2e-05 -0.001999</velocity>
          <acceleration>-0.026624 -0.030558 0.075735 -0.195101 -0.193064 2.31288</acceleration>
          <wrench>-0.006941 -0.007967 0.019745 0 -0 0</wrench>
        </link>
        <link name='LWrMot3'>
          <pose frame=''>0.793698 0.391623 0.466325 -9.1e-05 -0.003213 -0.393874</pose>
          <velocity>-1e-06 -1e-05 0.000113 0.000219 -0.000122 -0.001999</velocity>
          <acceleration>0.003869 0.003892 0.075312 0.596422 -0.52157 2.35102</acceleration>
          <wrench>0.00137 0.001378 0.026661 0 -0 0</wrench>
        </link>
        <link name='RElb'>
          <pose frame=''>0.687419 0.098415 0.661043 0.000109 -0.003225 -0.393849</pose>
          <velocity>1e-05 0.000218 1.5e-05 -0.000594 -0.000431 0.016617</velocity>
          <acceleration>-0.025204 0.444907 -0.031717 -3.13554 -1.07197 -0.98733</acceleration>
          <wrench>-0.015956 0.281657 -0.020079 0 -0 0</wrench>
        </link>
        <link name='RFoot'>
          <pose frame=''>0.700724 0.182906 0.089958 -4e-06 -0.000118 -0.394038</pose>
          <velocity>3e-06 0.000145 0.00013 -0.001639 4.8e-05 -1.2e-05</velocity>
          <acceleration>-0.123555 -0.007988 -0.046624 2.45261 0.430412 -2.57465</acceleration>
          <wrench>-0.082345 -0.005324 -0.031073 0 -0 0</wrench>
        </link>
        <link name='RFootmot'>
          <pose frame=''>0.700724 0.182905 0.089956 -2.3e-05 -0.000121 -0.394036</pose>
          <velocity>-3e-06 0.000124 0.000119 -0.002484 -0.000506 -0.000176</velocity>
          <acceleration>-0.265482 -0.096025 -0.07831 1.68135 -0.601162 -3.00034</acceleration>
          <wrench>-0.193781 -0.070091 -0.05716 0 -0 0</wrench>
        </link>
        <link name='RForearm'>
          <pose frame=''>0.673892 0.104048 0.553193 9.9e-05 -0.003241 -0.393863</pose>
          <velocity>-3.3e-05 -5.7e-05 5e-06 -0.000159 -0.000609 -0.012546</velocity>
          <acceleration>-0.075053 -0.118897 -0.05508 -0.593274 -1.36283 -0.402996</acceleration>
          <wrench>-0.070064 -0.110992 -0.051418 0 -0 0</wrench>
        </link>
        <link name='RHipMot'>
          <pose frame=''>0.719731 0.228778 0.516747 -0.000135 -0.000124 -0.393823</pose>
          <velocity>0.00036 -0.000172 8.3e-05 0.001261 0.003967 0.004486</velocity>
          <acceleration>0.260451 -0.129758 -0.056883 1.88103 -1.25186 -0.128428</acceleration>
          <wrench>0.232474 -0.11582 -0.050773 0 -0 0</wrench>
        </link>
        <link name='RLowLeg'>
          <pose frame=''>0.700711 0.182937 0.290955 -0.000116 -0.000123 -0.394028</pose>
          <velocity>-0.000305 0.000122 0.00011 -3e-06 -0.001501 -0.000285</velocity>
          <acceleration>-0.261403 -0.177725 -0.0893 0.430835 -0.496726 2.10747</acceleration>
          <wrench>-0.368531 -0.250561 -0.125897 0 -0 0</wrench>
        </link>
        <link name='RShp'>
          <pose frame=''>0.701189 0.172048 0.841004 -1.9e-05 -0.002961 -0.393866</pose>
          <velocity>-1.2e-05 8e-06 5.2e-05 0.000381 2.6e-05 -0.000409</velocity>
          <acceleration>-0.038286 0.047275 -0.009839 2.55713 -0.909364 -0.959854</acceleration>
          <wrench>-0.02174 0.026844 -0.005587 0 -0 0</wrench>
        </link>
        <link name='RShr'>
          <pose frame=''>0.673059 0.104361 0.841 0.000107 -0.003023 -0.393863</pose>
          <velocity>-4.1e-05 1.9e-05 2.1e-05 -0.000155 0.000197 -0.000407</velocity>
          <acceleration>-0.050175 0.053524 -0.009118 -2.90276 0.257735 2.19067</acceleration>
          <wrench>-0.038978 0.04158 -0.007083 0 -0 0</wrench>
        </link>
        <link name='RShy'>
          <pose frame=''>0.673186 0.104313 0.79619 0.000111 -0.003006 -0.393853</pose>
          <velocity>-5.1e-05 9e-06 1.9e-05 -0.000206 0.000272 0.016628</velocity>
          <acceleration>0.094588 0.009079 -0.01248 -2.61364 0.998302 1.39437</acceleration>
          <wrench>0.098961 0.009499 -0.013057 0 -0 0</wrench>
        </link>
        <link name='RThighLowLeg'>
          <pose frame=''>0.700703 0.182956 0.414354 -0.00012 -0.000113 -0.394025</pose>
          <velocity>0.000157 -0.000123 0.000106 0.002036 0.003724 -0.000302</velocity>
          <acceleration>-0.1346 -0.249142 -0.091941 1.71535 1.20798 -2.10975</acceleration>
          <wrench>-0.228834 -0.423568 -0.156309 0 -0 0</wrench>
        </link>
        <link name='RThighUpLeg'>
          <pose frame=''>0.700698 0.182974 0.516754 -0.000121 -0.000114 -0.393826</pose>
          <velocity>0.000555 -0.000279 0.00012 0.001971 0.003716 0.004515</velocity>
          <acceleration>0.201234 -0.205964 -0.032544 -2.3479 -0.415877 2.73155</acceleration>
          <wrench>0.206186 -0.211033 -0.033345 0 -0 0</wrench>
        </link>
        <link name='RWrMot2'>
          <pose frame=''>0.674155 0.103948 0.466313 9.9e-05 -0.003239 -0.393863</pose>
          <velocity>2e-05 -7.1e-05 4e-06 0.000483 0.000815 -0.012549</velocity>
          <acceleration>0.004475 -0.154038 -0.055314 0.616544 1.18578 -0.470624</acceleration>
          <wrench>0.001167 -0.040159 -0.014421 0 -0 0</wrench>
        </link>
        <link name='RWrMot3'>
          <pose frame=''>0.674155 0.103948 0.466312 9.9e-05 -0.003239 -0.393863</pose>
          <velocity>2e-05 -7e-05 4e-06 0.001131 0.000545 -0.012538</velocity>
          <acceleration>-0.025771 -0.020815 -0.056276 2.28881 0.490221 -0.386044</acceleration>
          <wrench>-0.009123 -0.007369 -0.019922 0 -0 0</wrench>
        </link>
        <link name='base_link'>
          <pose frame=''>0.728559 0.250016 0.516744 1.7e-05 -0.00013 -0.393873</pose>
          <velocity>0.000278 -0.000126 6.4e-05 -0.00124 -0.002873 0.00444</velocity>
          <acceleration>0.037243 -0.114977 -0.068242 -1.95316 -1.13275 0.064648</acceleration>
          <wrench>0.067443 -0.208208 -0.123577 0 -0 0</wrench>
        </link>
      </model>
      <model name='euro_pallet'>
        <pose frame=''>4.18684 0.259681 0.071997 0 1.2e-05 -0.011659</pose>
        <scale>1 1 1</scale>
        <link name='link'>
          <pose frame=''>4.18684 0.259681 0.071997 0 1.2e-05 -0.011659</pose>
          <velocity>0 0 0 0 -0 0</velocity>
          <acceleration>1.87684 -0.020876 -7.79125 0.480344 0.943125 -0.002529</acceleration>
          <wrench>37.5368 -0.417527 -155.825 0 -0 0</wrench>
        </link>
      </model>
      <model name='euro_pallet_0'>
        <pose frame=''>4.10195 -0.366915 0.552515 1.03434 -0 -0.024886</pose>
        <scale>1 1 1</scale>
        <link name='link'>
          <pose frame=''>4.10195 -0.366915 0.552515 1.03434 -0 -0.024886</pose>
          <velocity>0 0 0 0 -0 0</velocity>
          <acceleration>2.85648 1.046 0.974943 -1.12241 -0.398024 2.44404</acceleration>
          <wrench>57.1295 20.92 19.4989 0 -0 0</wrench>
        </link>
      </model>
      <model name='ground_plane'>
        <pose frame=''>0 0 0 0 -0 0</pose>
        <scale>1 1 1</scale>
        <link name='link'>
          <pose frame=''>0 0 0 0 -0 0</pose>
          <velocity>0 0 0 0 -0 0</velocity>
          <acceleration>0 0 0 0 -0 0</acceleration>
          <wrench>0 0 0 0 -0 0</wrench>
        </link>
      </model>
      <model name='visual_pattern'>
        <pose frame=''>3.7677 2.65007 3.54767 3.14159 -9.3e-05 3.14159</pose>
        <scale>1 1 1</scale>
        <link name='link'>
          <pose frame=''>3.7677 2.65007 3.54767 3.14159 -9.3e-05 3.14159</pose>
          <velocity>0 0 0 0 -0 0</velocity>
          <acceleration>0 0 0 0 -0 0</acceleration>
          <wrench>0 0 0 0 -0 0</wrench>
        </link>
      </model>
      <light name='sun'>
        <pose frame=''>0 0 10 0 -0 0</pose>
      </light>
      <light name='user_point_light_0'>
        <pose frame=''>3.46391 1 4.1261 0 -0 0</pose>
      </light>
    </state>
  </world>
</sdf>
